Workbook

Sheet Data
A1: Game | B1: Board | C1: Date | D1: Players | E1: Jeffrey | F1: Robert | G1: Bobby | H1: Stephen | I1: Cory | J1: Chelsea | K1: Robin | L1: Marcus | M1: Spencer | N1: Syvaunti | O1: Rob Elrod | P1: Cayla | Q1: Ethan | R1: Ruth | S1: Katie Zackarias | T1: John Zackarias | U1: Danielle | V1: Abby | W1: Georgia
A2: Carcassonne | C2: 43282 | D2: =COUNT(E2:Z2) -> 4 | E2: 2 | F2: 1 | G2: 3 | H2: 4
A3: Carcassonne | C3: 43285 | D3: =COUNT(E3:Z3) -> 4 | E3: 1 | F3: 2 | H3: 3 | I3: 4
A4: Carcassonne | C4: 43288 | D4: =COUNT(E4:Z4) -> 4 | E4: 2 | F4: 3 | K4: 1 | L4: 4
A5: Carcassonne | C5: 43296 | D5: =COUNT(E5:Z5) -> 3 | E5: 3 | F5: 1 | H5: 2
A6: Carcassonne | C6: 43317 | D6: =COUNT(E6:Z6) -> 4 | E6: 3 | F6: 4 | G6: 1 | H6: 2
A7: Carcassonne | C7: Unknown | D7: =COUNT(E7:Z7) -> 5 | E7: 5 | F7: 4 | G7: 2 | H7: 1 | M7: 3
A8: Carcassonne | C8: 43421 | D8: =COUNT(E8:Z8) -> 3 | E8: 2 | F8: 1 | H8: 3
A9: Carcassonne | C9: Unknown | D9: =COUNT(E9:Z9) -> 3 | E9: 2 | F9: 3 | H9: 1
A10: Carcassonne | C10: Unknown | D10: =COUNT(E10:Z10) -> 3 | E10: 2 | F10: 1 | I10: 3
A11: Carcassonne | C11: Unknown | D11: =COUNT(E11:Z11) -> 3 | E11: 2 | F11: 1 | G11: 3
A12: Carcassonne | C12: 43646 | D12: =COUNT(E12:Z12) -> 3 | E12: 3 | F12: 1 | H12: 2
A13: Dominion | C13: 43645 | D13: =COUNT(E13:Z13) -> 4 | E13: 2 | F13: 1 | H13: 4 | I13: 3
A14: King of New York | C14: Unknown | D14: =COUNT(E14:Z14) -> 3 | E14: 3 | F14: 1 | H14: 2
A15: King of New York | C15: Unknown | D15: =COUNT(E15:Z15) -> 3 | E15: 3 | F15: 1 | H15: 2
A16: King of New York | C16: Unknown | D16: =COUNT(E16:Z16) -> 3 | E16: 2 | F16: 1 | H16: 3
A17: King of New York | C17: Unknown | D17: =COUNT(E17:Z17) -> 3 | E17: 2 | F17: 1 | H17: 3
A18: King of New York | C18: Unknown | D18: =COUNT(E18:Z18) -> 3 | E18: 2 | F18: 1 | H18: 3
A19: King of New York | C19: Unknown | D19: =COUNT(E19:Z19) -> 3 | E19: 2 | F19: 1 | H19: 3
A20: King of New York | C20: Unknown | D20: =COUNT(E20:Z20) -> 3 | E20: 1 | F20: 2 | H20: 3
A21: King of New York | C21: Unknown | D21: =COUNT(E21:Z21) -> 3 | E21: 2 | F21: 3 | H21: 1
A22: King of New York | C22: Unknown | D22: =COUNT(E22:Z22) -> 3 | E22: 3 | F22: 1 | H22: 2
A23: King of New York | C23: Unknown | D23: =COUNT(E23:Z23) -> 3 | E23: 2 | F23: 1 | H23: 3
A24: King of New York | C24: Unknown | D24: =COUNT(E24:Z24) -> 3 | E24: 2 | F24: 3 | H24: 1
A25: King of New York | C25: Unknown | D25: =COUNT(E25:Z25) -> 3 | E25: 1 | F25: 2 | H25: 3
... A46: King of New York | C46: Unknown | D46: =COUNT(E46:Z46) -> 3 | E46: 1 | F46: 3 | H46: 2
A47: King of New York | C47: Unknown | D47: =COUNT(E47:Z47) -> 4 | E47: 3 | F47: 1 | H47: 4 | I47: 2
A48: King of New York | C48: 43576 | D48: =COUNT(E48:Z48) -> 4 | E48: 4 | F48: 2 | H48: 3 | I48: 1
A49: King of Tokyo | C49: Unknown | D49: =COUNT(E49:Z49) -> 3 | E49: 3 | F49: 2 | H49: 1
A50: King of Tokyo | C50: Unknown | D50: =COUNT(E50:Z50) -> 3 | E50: 3 | F50: 1 | H50: 2
A51: Monopoly | C51: 42763 | D51: =COUNT(E51:Z51) -> 4 | E51: 3 | F51: 4 | G51: 1 | J51: 2
A52: Monopoly | C52: 42763 | D52: =COUNT(E52:Z52) -> 4 | E52: 1 | F52: 2 | G52: 4 | J52: 3
A53: Monopoly | C53: 42764 | D53: =COUNT(E53:Z53) -> 4 | E53: 2 | F53: 3 | G53: 1 | J53: 4
A54: Monopoly | C54: 42862 | D54: =COUNT(E54:Z54) -> 4 | E54: 3 | F54: 4 | G54: 2 | J54: 1
A55: Monopoly | C55: 43002 | D55: =COUNT(E55:Z55) -> 3 | E55: 2 | F55: 3 | G55: 1
A56: Monopoly | C56: 43005 | D56: =COUNT(E56:Z56) -> 3 | E56: 3 | F56: 1 | G56: 2
A57: Monopoly | C57: 43018 | D57: =COUNT(E57:Z57) -> 3 | E57: 1 | F57: 3 | G57: 2
A58: Monopoly | C58: 43034 | D58: =COUNT(E58:Z58) -> 3 | E58: 1 | F58: 3 | G58: 2
A59: Monopoly | C59: 43037 | D59: =COUNT(E59:Z59) -> 3 | E59: 2 | F59: 3 | G59: 1
A60: Monopoly | C60: 43041 | D60: =COUNT(E60:Z60) -> 3 | E60: 2 | F60: 3 | G60: 1
...

Sheet Backgammon
A1: Date | B1: Winner | C1: Loser | D1: Skunk
A2: 44381 | B2: Robert | C2: Jeffrey | D2: 1
A3: 44381 | B3: Robert | C3: Jeffrey
A4: 44381 | B4: Robert | C4: Jeffrey
A5: 44381 | B5: Jeffrey | C5: Robert
A6: 44381 | B6: Jeffrey | C6: Robert
A7: 44395 | B7: Robert | C7: Jeffrey
A8: 44395 | B8: Jeffrey | C8: Robert
A9: 44395 | B9: Robert | C9: Jeffrey
A10: 44407 | B10: Robert | C10: Jeffrey | D10: 1
A11: 44407 | B11: Jeffrey | C11: Robert
A12: 44407 | B12: Robert | C12: Jeffrey
A13: 44408 | B13: Jeffrey | C13: Robert
A14: 44408 | B14: Robert | C14: Jeffrey
A15: 44408 | B15: Jeffrey | C15: Robert
A16: 44409 | B16: Jeffrey | C16: Robert | D16: 1
A17: 44409 | B17: Jeffrey | C17: Robert
A18: 44445 | B18: Robert | C18: Jeffrey
A19: 44445 | B19: Robert | C19: Jeffrey
A20: 44472 | B20: Robert | C20: Jeffrey

Sheet Average Rank
A1: 5 | B1: Count | C1: =Data!E1 -> Jeffrey | D1: =Data!F1 -> Robert | E1: =Data!G1 -> Bobby | F1: =Data!H1 -> Stephen | G1: =Data!I1 -> Cory | H1: =Data!J1 -> Chelsea | I1: =Data!K1 -> Robin | J1: =Data!L1 -> Marcus | ... T1: =Data!V1 -> Abby
A2: Carcassonne | B2: =countif(Data!A:A,"="&A2) -> 24 | C2: =if(countifs(Data!$A:$A,"="&$A2,Data!E:E,">0")>=$A$1,AVERAGEIF(Data!$A:$A,"="&$A2,Data!E:E),"") -> 2.2083333 | D2: =if(countifs(Data!$A:$A,"="&$A2,Data!F:F,">0")>=$A$1,AVERAGEIF(Data!$A:$A,"="&$A2,Data!F:F),"") -> 2.1666667 | E2: =if(countifs(Data!$A:$A,"="&$A2,Data!G:G,">0")>=$A$1,AVERAGEIF(Data!$A:$A,"="&$A2,Data!G:G),"") -> 2.1428571 | F2: =if(countifs(Data!$A:$A,"="&$A2,Data!H:H,">0")>=$A$1,AVERAGEIF(Data!$A:$A,"="&$A2,Data!H:H),"") -> 2.2941176 | G2: =if(countifs(Data!$A:$A,"="&$A2,Data!I:I,">0")>=$A$1,AVERAGEIF(Data!$A:$A,"="&$A2,Data!I:I),"") | H2: =if(countifs(Data!$A:$A,"="&$A2,Data!J:J,">0")>=$A$1,AVERAGEIF(Data!$A:$A,"="&$A2,Data!J:J),"") | I2: =if(countifs(Data!$A:$A,"="&$A2,Data!K:K,">0")>=$A$1,AVERAGEIF(Data!$A:$A,"="&$A2,Data!K:K),"") | J2: =if(countifs(Data!$A:$A,"="&$A2,Data!L:L,">0")>=$A$1,AVERAGEIF(Data!$A:$A,"="&$A2,Data!L:L),"") | K2: =if(countifs(Data!$A:$A,"="&$A2,Data!M:M,">0")>=$A$1,AVERAGEIF(Data!$A:$A,"="&$A2,Data!M:M),"") | L2: =if(countifs(Data!$A:$A,"="&$A2,Data!N:N,">0")>=$A$1,AVERAGEIF(Data!$A:$A,"="&$A2,Data!N:N),"") | M2: =if(countifs(Data!$A:$A,"="&$A2,Data!O:O,">0")>=$A$1,AVERAGEIF(Data!$A:$A,"="&$A2,Data!O:O),"") | N2: =if(countifs(Data!$A:$A,"="&$A2,Data!P:P,">0")>=$A$1,AVERAGEIF(Data!$A:$A,"="&$A2,Data!P:P),"") | O2: =if(countifs(Data!$A:$A,"="&$A2,Data!Q:Q,">0")>=$A$1,AVERAGEIF(Data!$A:$A,"="&$A2,Data!Q:Q),"") | P2: =if(countifs(Data!$A:$A,"="&$A2,Data!R:R,">0")>=$A$1,AVERAGEIF(Data!$A:$A,"="&$A2,Data!R:R),"") | Q2: =if(countifs(Data!$A:$A,"="&$A2,Data!S:S,">0")>=$A$1,AVERAGEIF(Data!$A:$A,"="&$A2,Data!S:S),"") | R2: =if(countifs(Data!$A:$A,"="&$A2,Data!T:T,">0")>=$A$1,AVERAGEIF(Data!$A:$A,"="&$A2,Data!T:T),"") | S2: =if(countifs(Data!$A:$A,"="&$A2,Data!U:U,">0")>=$A$1,AVERAGEIF(Data!$A:$A,"="&$A2,Data!U:U),"") | T2: =if(countifs(Data!$A:$A,"="&$A2,Data!V:V,">0")>=$A$1,AVERAGEIF(Data!$A:$A,"="&$A2,Data!V:V),"")
A3: Dominion | B3: =countif(Data!A:A,"="&A3) -> 3 | C3: =if(countifs(Data!$A:$A,"="&$A3,Data!E:E,">0")>=$A$1,AVERAGEIF(Data!$A:$A,"="&$A3,Data!E:E),"") | D3: =if(countifs(Data!$A:$A,"="&$A3,Data!F:F,">0")>=$A$1,AVERAGEIF(Data!$A:$A,"="&$A3,Data!F:F),"") | E3: =if(countifs(Data!$A:$A,"="&$A3,Data!G:G,">0")>=$A$1,AVERAGEIF(Data!$A:$A,"="&$A3,Data!G:G),"") | F3: =if(countifs(Data!$A:$A,"="&$A3,Data!H:H,">0")>=$A$1,AVERAGEIF(Data!$A:$A,"="&$A3,Data!H:H),"") | G3: =if(countifs(Data!$A:$A,"="&$A3,Data!I:I,">0")>=$A$1,AVERAGEIF(Data!$A:$A,"="&$A3,Data!I:I),"") | H3: =if(countifs(Data!$A:$A,"="&$A3,Data!J:J,">0")>=$A$1,AVERAGEIF(Data!$A:$A,"="&$A3,Data!J:J),"") | I3: =if(countifs(Data!$A:$A,"="&$A3,Data!K:K,">0")>=$A$1,AVERAGEIF(Data!$A:$A,"="&$A3,Data!K:K),"") | J3: =if(countifs(Data!$A:$A,"="&$A3,Data!L:L,">0")>=$A$1,AVERAGEIF(Data!$A:$A,"="&$A3,Data!L:L),"") | K3: =if(countifs(Data!$A:$A,"="&$A3,Data!M:M,">0")>=$A$1,AVERAGEIF(Data!$A:$A,"="&$A3,Data!M:M),"") | L3: =if(countifs(Data!$A:$A,"="&$A3,Data!N:N,">0")>=$A$1,AVERAGEIF(Data!$A:$A,"="&$A3,Data!N:N),"") | M3: =if(countifs(Data!$A:$A,"="&$A3,Data!O:O,">0")>=$A$1,AVERAGEIF(Data!$A:$A,"="&$A3,Data!O:O),"") | N3: =if(countifs(Data!$A:$A,"="&$A3,Data!P:P,">0")>=$A$1,AVERAGEIF(Data!$A:$A,"="&$A3,Data!P:P),"") | O3: =if(countifs(Data!$A:$A,"="&$A3,Data!Q:Q,">0")>=$A$1,AVERAGEIF(Data!$A:$A,"="&$A3,Data!Q:Q),"") | P3: =if(countifs(Data!$A:$A,"="&$A3,Data!R:R,">0")>=$A$1,AVERAGEIF(Data!$A:$A,"="&$A3,Data!R:R),"") | Q3: =if(countifs(Data!$A:$A,"="&$A3,Data!S:S,">0")>=$A$1,AVERAGEIF(Data!$A:$A,"="&$A3,Data!S:S),"") | R3: =if(countifs(Data!$A:$A,"="&$A3,Data!T:T,">0")>=$A$1,AVERAGEIF(Data!$A:$A,"="&$A3,Data!T:T),"") | S3: =if(countifs(Data!$A:$A,"="&$A3,Data!U:U,">0")>=$A$1,AVERAGEIF(Data!$A:$A,"="&$A3,Data!U:U),"") | T3: =if(countifs(Data!$A:$A,"="&$A3,Data!V:V,">0")>=$A$1,AVERAGEIF(Data!$A:$A,"="&$A3,Data!V:V),"")
A4: King of New York | B4: =countif(Data!A:A,"="&A4) -> 57 | C4: =if(countifs(Data!$A:$A,"="&$A4,Data!E:E,">0")>=$A$1,AVERAGEIF(Data!$A:$A,"="&$A4,Data!E:E),"") -> 2.1052632 | D4: =if(countifs(Data!$A:$A,"="&$A4,Data!F:F,">0")>=$A$1,AVERAGEIF(Data!$A:$A,"="&$A4,Data!F:F),"") -> 1.9464286 | E4: =if(countifs(Data!$A:$A,"="&$A4,Data!G:G,">0")>=$A$1,AVERAGEIF(Data!$A:$A,"="&$A4,Data!G:G),"") | F4: =if(countifs(Data!$A:$A,"="&$A4,Data!H:H,">0")>=$A$1,AVERAGEIF(Data!$A:$A,"="&$A4,Data!H:H),"") -> 2.2105263 | G4: =if(countifs(Data!$A:$A,"="&$A4,Data!I:I,">0")>=$A$1,AVERAGEIF(Data!$A:$A,"="&$A4,Data!I:I),"") -> 2.2 | H4: =if(countifs(Data!$A:$A,"="&$A4,Data!J:J,">0")>=$A$1,AVERAGEIF(Data!$A:$A,"="&$A4,Data!J:J),"") | I4: =if(countifs(Data!$A:$A,"="&$A4,Data!K:K,">0")>=$A$1,AVERAGEIF(Data!$A:$A,"="&$A4,Data!K:K),"") | J4: =if(countifs(Data!$A:$A,"="&$A4,Data!L:L,">0")>=$A$1,AVERAGEIF(Data!$A:$A,"="&$A4,Data!L:L),"") | K4: =if(countifs(Data!$A:$A,"="&$A4,Data!M:M,">0")>=$A$1,AVERAGEIF(Data!$A:$A,"="&$A4,Data!M:M),"") | L4: =if(countifs(Data!$A:$A,"="&$A4,Data!N:N,">0")>=$A$1,AVERAGEIF(Data!$A:$A,"="&$A4,Data!N:N),"") | M4: =if(countifs(Data!$A:$A,"="&$A4,Data!O:O,">0")>=$A$1,AVERAGEIF(Data!$A:$A,"="&$A4,Data!O:O),"") | N4: =if(countifs(Data!$A:$A,"="&$A4,Data!P:P,">0")>=$A$1,AVERAGEIF(Data!$A:$A,"="&$A4,Data!P:P),"") | O4: =if(countifs(Data!$A:$A,"="&$A4,Data!Q:Q,">0")>=$A$1,AVERAGEIF(Data!$A:$A,"="&$A4,Data!Q:Q),"") | P4: =if(countifs(Data!$A:$A,"="&$A4,Data!R:R,">0")>=$A$1,AVERAGEIF(Data!$A:$A,"="&$A4,Data!R:R),"") | Q4: =if(countifs(Data!$A:$A,"="&$A4,Data!S:S,">0")>=$A$1,AVERAGEIF(Data!$A:$A,"="&$A4,Data!S:S),"") | R4: =if(countifs(Data!$A:$A,"="&$A4,Data!T:T,">0")>=$A$1,AVERAGEIF(Data!$A:$A,"="&$A4,Data!T:T),"") | S4: =if(countifs(Data!$A:$A,"="&$A4,Data!U:U,">0")>=$A$1,AVERAGEIF(Data!$A:$A,"="&$A4,Data!U:U),"") | T4: =if(countifs(Data!$A:$A,"="&$A4,Data!V:V,">0")>=$A$1,AVERAGEIF(Data!$A:$A,"="&$A4,Data!V:V),"")
A5: King of Tokyo | B5: =countif(Data!A:A,"="&A5) -> 17 | C5: =if(countifs(Data!$A:$A,"="&$A5,Data!E:E,">0")>=$A$1,AVERAGEIF(Data!$A:$A,"="&$A5,Data!E:E),"") -> 2.1176471 | D5: =if(countifs(Data!$A:$A,"="&$A5,Data!F:F,">0")>=$A$1,AVERAGEIF(Data!$A:$A,"="&$A5,Data!F:F),"") -> 2 | E5: =if(countifs(Data!$A:$A,"="&$A5,Data!G:G,">0")>=$A$1,AVERAGEIF(Data!$A:$A,"="&$A5,Data!G:G),"") | F5: =if(countifs(Data!$A:$A,"="&$A5,Data!H:H,">0")>=$A$1,AVERAGEIF(Data!$A:$A,"="&$A5,Data!H:H),"") -> 1.8888889 | G5: =if(countifs(Data!$A:$A,"="&$A5,Data!I:I,">0")>=$A$1,AVERAGEIF(Data!$A:$A,"="&$A5,Data!I:I),"") | H5: =if(countifs(Data!$A:$A,"="&$A5,Data!J:J,">0")>=$A$1,AVERAGEIF(Data!$A:$A,"="&$A5,Data!J:J),"") | I5: =if(countifs(Data!$A:$A,"="&$A5,Data!K:K,">0")>=$A$1,AVERAGEIF(Data!$A:$A,"="&$A5,Data!K:K),"") | J5: =if(countifs(Data!$A:$A,"="&$A5,Data!L:L,">0")>=$A$1,AVERAGEIF(Data!$A:$A,"="&$A5,Data!L:L),"") | K5: =if(countifs(Data!$A:$A,"="&$A5,Data!M:M,">0")>=$A$1,AVERAGEIF(Data!$A:$A,"="&$A5,Data!M:M),"") -> 2 | L5: =if(countifs(Data!$A:$A,"="&$A5,Data!N:N,">0")>=$A$1,AVERAGEIF(Data!$A:$A,"="&$A5,Data!N:N),"") | M5: =if(countifs(Data!$A:$A,"="&$A5,Data!O:O,">0")>=$A$1,AVERAGEIF(Data!$A:$A,"="&$A5,Data!O:O),"") | N5: =if(countifs(Data!$A:$A,"="&$A5,Data!P:P,">0")>=$A$1,AVERAGEIF(Data!$A:$A,"="&$A5,Data!P:P),"") | O5: =if(countifs(Data!$A:$A,"="&$A5,Data!Q:Q,">0")>=$A$1,AVERAGEIF(Data!$A:$A,"="&$A5,Data!Q:Q),"") | P5: =if(countifs(Data!$A:$A,"="&$A5,Data!R:R,">0")>=$A$1,AVERAGEIF(Data!$A:$A,"="&$A5,Data!R:R),"") | Q5: =if(countifs(Data!$A:$A,"="&$A5,Data!S:S,">0")>=$A$1,AVERAGEIF(Data!$A:$A,"="&$A5,Data!S:S),"") | R5: =if(countifs(Data!$A:$A,"="&$A5,Data!T:T,">0")>=$A$1,AVERAGEIF(Data!$A:$A,"="&$A5,Data!T:T),"") | S5: =if(countifs(Data!$A:$A,"="&$A5,Data!U:U,">0")>=$A$1,AVERAGEIF(Data!$A:$A,"="&$A5,Data!U:U),"") | T5: =if(countifs(Data!$A:$A,"="&$A5,Data!V:V,">0")>=$A$1,AVERAGEIF(Data!$A:$A,"="&$A5,Data!V:V),"")
A6: Monopoly | B6: =countif(Data!A:A,"="&A6) -> 269 | C6: =if(countifs(Data!$A:$A,"="&$A6,Data!E:E,">0")>=$A$1,AVERAGEIF(Data!$A:$A,"="&$A6,Data!E:E),"") -> 2.070632 | D6: =if(countifs(Data!$A:$A,"="&$A6,Data!F:F,">0")>=$A$1,AVERAGEIF(Data!$A:$A,"="&$A6,Data!F:F),"") -> 2.0594796 | E6: =if(countifs(Data!$A:$A,"="&$A6,Data!G:G,">0")>=$A$1,AVERAGEIF(Data!$A:$A,"="&$A6,Data!G:G),"") -> 2.0634328 | F6: =if(countifs(Data!$A:$A,"="&$A6,Data!H:H,">0")>=$A$1,AVERAGEIF(Data!$A:$A,"="&$A6,Data!H:H),"") -> 3.1 | G6: =if(countifs(Data!$A:$A,"="&$A6,Data!I:I,">0")>=$A$1,AVERAGEIF(Data!$A:$A,"="&$A6,Data!I:I),"") | H6: =if(countifs(Data!$A:$A,"="&$A6,Data!J:J,">0")>=$A$1,AVERAGEIF(Data!$A:$A,"="&$A6,Data!J:J),"") -> 3 | I6: =if(countifs(Data!$A:$A,"="&$A6,Data!K:K,">0")>=$A$1,AVERAGEIF(Data!$A:$A,"="&$A6,Data!K:K),"") | J6: =if(countifs(Data!$A:$A,"="&$A6,Data!L:L,">0")>=$A$1,AVERAGEIF(Data!$A:$A,"="&$A6,Data!L:L),"") | K6: =if(countifs(Data!$A:$A,"="&$A6,Data!M:M,">0")>=$A$1,AVERAGEIF(Data!$A:$A,"="&$A6,Data!M:M),"") | L6: =if(countifs(Data!$A:$A,"="&$A6,Data!N:N,">0")>=$A$1,AVERAGEIF(Data!$A:$A,"="&$A6,Data!N:N),"") | M6: =if(countifs(Data!$A:$A,"="&$A6,Data!O:O,">0")>=$A$1,AVERAGEIF(Data!$A:$A,"="&$A6,Data!O:O),"") | N6: =if(countifs(Data!$A:$A,"="&$A6,Data!P:P,">0")>=$A$1,AVERAGEIF(Data!$A:$A,"="&$A6,Data!P:P),"") | O6: =if(countifs(Data!$A:$A,"="&$A6,Data!Q:Q,">0")>=$A$1,AVERAGEIF(Data!$A:$A,"="&$A6,Data!Q:Q),"") | P6: =if(countifs(Data!$A:$A,"="&$A6,Data!R:R,">0")>=$A$1,AVERAGEIF(Data!$A:$A,"="&$A6,Data!R:R),"") | Q6: =if(countifs(Data!$A:$A,"="&$A6,Data!S:S,">0")>=$A$1,AVERAGEIF(Data!$A:$A,"="&$A6,Data!S:S),"") | R6: =if(countifs(Data!$A:$A,"="&$A6,Data!T:T,">0")>=$A$1,AVERAGEIF(Data!$A:$A,"="&$A6,Data!T:T),"") | S6: =if(countifs(Data!$A:$A,"="&$A6,Data!U:U,">0")>=$A$1,AVERAGEIF(Data!$A:$A,"="&$A6,Data!U:U),"") | T6: =if(countifs(Data!$A:$A,"="&$A6,Data!V:V,">0")>=$A$1,AVERAGEIF(Data!$A:$A,"="&$A6,Data!V:V),"")
A7: Sheriff of Nottingham | B7: =countif(Data!A:A,"="&A7) -> 7 | C7: =if(countifs(Data!$A:$A,"="&$A7,Data!E:E,">0")>=$A$1,AVERAGEIF(Data!$A:$A,"="&$A7,Data!E:E),"") -> 2.1428571 | D7: =if(countifs(Data!$A:$A,"="&$A7,Data!F:F,">0")>=$A$1,AVERAGEIF(Data!$A:$A,"="&$A7,Data!F:F),"") -> 2.1666667 | E7: =if(countifs(Data!$A:$A,"="&$A7,Data!G:G,">0")>=$A$1,AVERAGEIF(Data!$A:$A,"="&$A7,Data!G:G),"") | F7: =if(countifs(Data!$A:$A,"="&$A7,Data!H:H,">0")>=$A$1,AVERAGEIF(Data!$A:$A,"="&$A7,Data!H:H),"") -> 2.5 | G7: =if(countifs(Data!$A:$A,"="&$A7,Data!I:I,">0")>=$A$1,AVERAGEIF(Data!$A:$A,"="&$A7,Data!I:I),"") | H7: =if(countifs(Data!$A:$A,"="&$A7,Data!J:J,">0")>=$A$1,AVERAGEIF(Data!$A:$A,"="&$A7,Data!J:J),"") | I7: =if(countifs(Data!$A:$A,"="&$A7,Data!K:K,">0")>=$A$1,AVERAGEIF(Data!$A:$A,"="&$A7,Data!K:K),"") | J7: =if(countifs(Data!$A:$A,"="&$A7,Data!L:L,">0")>=$A$1,AVERAGEIF(Data!$A:$A,"="&$A7,Data!L:L),"") | K7: =if(countifs(Data!$A:$A,"="&$A7,Data!M:M,">0")>=$A$1,AVERAGEIF(Data!$A:$A,"="&$A7,Data!M:M),"") | L7: =if(countifs(Data!$A:$A,"="&$A7,Data!N:N,">0")>=$A$1,AVERAGEIF(Data!$A:$A,"="&$A7,Data!N:N),"") | M7: =if(countifs(Data!$A:$A,"="&$A7,Data!O:O,">0")>=$A$1,AVERAGEIF(Data!$A:$A,"="&$A7,Data!O:O),"") | N7: =if(countifs(Data!$A:$A,"="&$A7,Data!P:P,">0")>=$A$1,AVERAGEIF(Data!$A:$A,"="&$A7,Data!P:P),"") | O7: =if(countifs(Data!$A:$A,"="&$A7,Data!Q:Q,">0")>=$A$1,AVERAGEIF(Data!$A:$A,"="&$A7,Data!Q:Q),"") | P7: =if(countifs(Data!$A:$A,"="&$A7,Data!R:R,">0")>=$A$1,AVERAGEIF(Data!$A:$A,"="&$A7,Data!R:R),"") | Q7: =if(countifs(Data!$A:$A,"="&$A7,Data!S:S,">0")>=$A$1,AVERAGEIF(Data!$A:$A,"="&$A7,Data!S:S),"") | R7: =if(countifs(Data!$A:$A,"="&$A7,Data!T:T,">0")>=$A$1,AVERAGEIF(Data!$A:$A,"="&$A7,Data!T:T),"") | S7: =if(countifs(Data!$A:$A,"="&$A7,Data!U:U,">0")>=$A$1,AVERAGEIF(Data!$A:$A,"="&$A7,Data!U:U),"") | T7: =if(countifs(Data!$A:$A,"="&$A7,Data!V:V,">0")>=$A$1,AVERAGEIF(Data!$A:$A,"="&$A7,Data!V:V),"")
A8: Snapshouts | B8: =countif(Data!A:A,"="&A8) -> 1 | C8: =if(countifs(Data!$A:$A,"="&$A8,Data!E:E,">0")>=$A$1,AVERAGEIF(Data!$A:$A,"="&$A8,Data!E:E),"") | D8: =if(countifs(Data!$A:$A,"="&$A8,Data!F:F,">0")>=$A$1,AVERAGEIF(Data!$A:$A,"="&$A8,Data!F:F),"") | E8: =if(countifs(Data!$A:$A,"="&$A8,Data!G:G,">0")>=$A$1,AVERAGEIF(Data!$A:$A,"="&$A8,Data!G:G),"") | F8: =if(countifs(Data!$A:$A,"="&$A8,Data!H:H,">0")>=$A$1,AVERAGEIF(Data!$A:$A,"="&$A8,Data!H:H),"") | G8: =if(countifs(Data!$A:$A,"="&$A8,Data!I:I,">0")>=$A$1,AVERAGEIF(Data!$A:$A,"="&$A8,Data!I:I),"") | H8: =if(countifs(Data!$A:$A,"="&$A8,Data!J:J,">0")>=$A$1,AVERAGEIF(Data!$A:$A,"="&$A8,Data!J:J),"") | I8: =if(countifs(Data!$A:$A,"="&$A8,Data!K:K,">0")>=$A$1,AVERAGEIF(Data!$A:$A,"="&$A8,Data!K:K),"") | J8: =if(countifs(Data!$A:$A,"="&$A8,Data!L:L,">0")>=$A$1,AVERAGEIF(Data!$A:$A,"="&$A8,Data!L:L),"") | K8: =if(countifs(Data!$A:$A,"="&$A8,Data!M:M,">0")>=$A$1,AVERAGEIF(Data!$A:$A,"="&$A8,Data!M:M),"") | L8: =if(countifs(Data!$A:$A,"="&$A8,Data!N:N,">0")>=$A$1,AVERAGEIF(Data!$A:$A,"="&$A8,Data!N:N),"") | M8: =if(countifs(Data!$A:$A,"="&$A8,Data!O:O,">0")>=$A$1,AVERAGEIF(Data!$A:$A,"="&$A8,Data!O:O),"") | N8: =if(countifs(Data!$A:$A,"="&$A8,Data!P:P,">0")>=$A$1,AVERAGEIF(Data!$A:$A,"="&$A8,Data!P:P),"") | O8: =if(countifs(Data!$A:$A,"="&$A8,Data!Q:Q,">0")>=$A$1,AVERAGEIF(Data!$A:$A,"="&$A8,Data!Q:Q),"") | P8: =if(countifs(Data!$A:$A,"="&$A8,Data!R:R,">0")>=$A$1,AVERAGEIF(Data!$A:$A,"="&$A8,Data!R:R),"") | Q8: =if(countifs(Data!$A:$A,"="&$A8,Data!S:S,">0")>=$A$1,AVERAGEIF(Data!$A:$A,"="&$A8,Data!S:S),"") | R8: =if(countifs(Data!$A:$A,"="&$A8,Data!T:T,">0")>=$A$1,AVERAGEIF(Data!$A:$A,"="&$A8,Data!T:T),"") | S8: =if(countifs(Data!$A:$A,"="&$A8,Data!U:U,">0")>=$A$1,AVERAGEIF(Data!$A:$A,"="&$A8,Data!U:U),"") | T8: =if(countifs(Data!$A:$A,"="&$A8,Data!V:V,">0")>=$A$1,AVERAGEIF(Data!$A:$A,"="&$A8,Data!V:V),"")
A9: Terraforming Mars | B9: =countif(Data!A:A,"="&A9) -> 60 | C9: =if(countifs(Data!$A:$A,"="&$A9,Data!E:E,">0")>=$A$1,AVERAGEIF(Data!$A:$A,"="&$A9,Data!E:E),"") -> 1.9166667 | D9: =if(countifs(Data!$A:$A,"="&$A9,Data!F:F,">0")>=$A$1,AVERAGEIF(Data!$A:$A,"="&$A9,Data!F:F),"") -> 1.6551724 | E9: =if(countifs(Data!$A:$A,"="&$A9,Data!G:G,">0")>=$A$1,AVERAGEIF(Data!$A:$A,"="&$A9,Data!G:G),"") | F9: =if(countifs(Data!$A:$A,"="&$A9,Data!H:H,">0")>=$A$1,AVERAGEIF(Data!$A:$A,"="&$A9,Data!H:H),"") -> 2.3793103 | G9: =if(countifs(Data!$A:$A,"="&$A9,Data!I:I,">0")>=$A$1,AVERAGEIF(Data!$A:$A,"="&$A9,Data!I:I),"") -> 2.8333333 | H9: =if(countifs(Data!$A:$A,"="&$A9,Data!J:J,">0")>=$A$1,AVERAGEIF(Data!$A:$A,"="&$A9,Data!J:J),"") | I9: =if(countifs(Data!$A:$A,"="&$A9,Data!K:K,">0")>=$A$1,AVERAGEIF(Data!$A:$A,"="&$A9,Data!K:K),"") | J9: =if(countifs(Data!$A:$A,"="&$A9,Data!L:L,">0")>=$A$1,AVERAGEIF(Data!$A:$A,"="&$A9,Data!L:L),"") | K9: =if(countifs(Data!$A:$A,"="&$A9,Data!M:M,">0")>=$A$1,AVERAGEIF(Data!$A:$A,"="&$A9,Data!M:M),"") | L9: =if(countifs(Data!$A:$A,"="&$A9,Data!N:N,">0")>=$A$1,AVERAGEIF(Data!$A:$A,"="&$A9,Data!N:N),"") | M9: =if(countifs(Data!$A:$A,"="&$A9,Data!O:O,">0")>=$A$1,AVERAGEIF(Data!$A:$A,"="&$A9,Data!O:O),"") | N9: =if(countifs(Data!$A:$A,"="&$A9,Data!P:P,">0")>=$A$1,AVERAGEIF(Data!$A:$A,"="&$A9,Data!P:P),"") | O9: =if(countifs(Data!$A:$A,"="&$A9,Data!Q:Q,">0")>=$A$1,AVERAGEIF(Data!$A:$A,"="&$A9,Data!Q:Q),"") | P9: =if(countifs(Data!$A:$A,"="&$A9,Data!R:R,">0")>=$A$1,AVERAGEIF(Data!$A:$A,"="&$A9,Data!R:R),"") | Q9: =if(countifs(Data!$A:$A,"="&$A9,Data!S:S,">0")>=$A$1,AVERAGEIF(Data!$A:$A,"="&$A9,Data!S:S),"") | R9: =if(countifs(Data!$A:$A,"="&$A9,Data!T:T,">0")>=$A$1,AVERAGEIF(Data!$A:$A,"="&$A9,Data!T:T),"") | S9: =if(countifs(Data!$A:$A,"="&$A9,Data!U:U,">0")>=$A$1,AVERAGEIF(Data!$A:$A,"="&$A9,Data!U:U),"") | T9: =if(countifs(Data!$A:$A,"="&$A9,Data!V:V,">0")>=$A$1,AVERAGEIF(Data!$A:$A,"="&$A9,Data!V:V),"")
A10: Ticket To Ride | B10: =countif(Data!A:A,"="&A10) -> 14 | C10: =if(countifs(Data!$A:$A,"="&$A10,Data!E:E,">0")>=$A$1,AVERAGEIF(Data!$A:$A,"="&$A10,Data!E:E),"") -> 1.5384615 | D10: =if(countifs(Data!$A:$A,"="&$A10,Data!F:F,">0")>=$A$1,AVERAGEIF(Data!$A:$A,"="&$A10,Data!F:F),"") -> 2.2142857 | E10: =if(countifs(Data!$A:$A,"="&$A10,Data!G:G,">0")>=$A$1,AVERAGEIF(Data!$A:$A,"="&$A10,Data!G:G),"") -> 1.8888889 | F10: =if(countifs(Data!$A:$A,"="&$A10,Data!H:H,">0")>=$A$1,AVERAGEIF(Data!$A:$A,"="&$A10,Data!H:H),"") -> 3.2 | G10: =if(countifs(Data!$A:$A,"="&$A10,Data!I:I,">0")>=$A$1,AVERAGEIF(Data!$A:$A,"="&$A10,Data!I:I),"") | H10: =if(countifs(Data!$A:$A,"="&$A10,Data!J:J,">0")>=$A$1,AVERAGEIF(Data!$A:$A,"="&$A10,Data!J:J),"") | I10: =if(countifs(Data!$A:$A,"="&$A10,Data!K:K,">0")>=$A$1,AVERAGEIF(Data!$A:$A,"="&$A10,Data!K:K),"") | J10: =if(countifs(Data!$A:$A,"="&$A10,Data!L:L,">0")>=$A$1,AVERAGEIF(Data!$A:$A,"="&$A10,Data!L:L),"") | K10: =if(countifs(Data!$A:$A,"="&$A10,Data!M:M,">0")>=$A$1,AVERAGEIF(Data!$A:$A,"="&$A10,Data!M:M),"") | L10: =if(countifs(Data!$A:$A,"="&$A10,Data!N:N,">0")>=$A$1,AVERAGEIF(Data!$A:$A,"="&$A10,Data!N:N),"") | M10: =if(countifs(Data!$A:$A,"="&$A10,Data!O:O,">0")>=$A$1,AVERAGEIF(Data!$A:$A,"="&$A10,Data!O:O),"") | N10: =if(countifs(Data!$A:$A,"="&$A10,Data!P:P,">0")>=$A$1,AVERAGEIF(Data!$A:$A,"="&$A10,Data!P:P),"") | O10: =if(countifs(Data!$A:$A,"="&$A10,Data!Q:Q,">0")>=$A$1,AVERAGEIF(Data!$A:$A,"="&$A10,Data!Q:Q),"") | P10: =if(countifs(Data!$A:$A,"="&$A10,Data!R:R,">0")>=$A$1,AVERAGEIF(Data!$A:$A,"="&$A10,Data!R:R),"") | Q10: =if(countifs(Data!$A:$A,"="&$A10,Data!S:S,">0")>=$A$1,AVERAGEIF(Data!$A:$A,"="&$A10,Data!S:S),"") | R10: =if(countifs(Data!$A:$A,"="&$A10,Data!T:T,">0")>=$A$1,AVERAGEIF(Data!$A:$A,"="&$A10,Data!T:T),"") | S10: =if(countifs(Data!$A:$A,"="&$A10,Data!U:U,">0")>=$A$1,AVERAGEIF(Data!$A:$A,"="&$A10,Data!U:U),"") | T10: =if(countifs(Data!$A:$A,"="&$A10,Data!V:V,">0")>=$A$1,AVERAGEIF(Data!$A:$A,"="&$A10,Data!V:V),"")
A11: Yahtzee | B11: =countif(Data!A:A,"="&A11) -> 12 | C11: =if(countifs(Data!$A:$A,"="&$A11,Data!E:E,">0")>=$A$1,AVERAGEIF(Data!$A:$A,"="&$A11,Data!E:E),"") -> 1.9166667 | D11: =if(countifs(Data!$A:$A,"="&$A11,Data!F:F,">0")>=$A$1,AVERAGEIF(Data!$A:$A,"="&$A11,Data!F:F),"") -> 2.2727273 | E11: =if(countifs(Data!$A:$A,"="&$A11,Data!G:G,">0")>=$A$1,AVERAGEIF(Data!$A:$A,"="&$A11,Data!G:G),"") -> 2.5 | F11: =if(countifs(Data!$A:$A,"="&$A11,Data!H:H,">0")>=$A$1,AVERAGEIF(Data!$A:$A,"="&$A11,Data!H:H),"") -> 2.5714286 | G11: =if(countifs(Data!$A:$A,"="&$A11,Data!I:I,">0")>=$A$1,AVERAGEIF(Data!$A:$A,"="&$A11,Data!I:I),"") | H11: =if(countifs(Data!$A:$A,"="&$A11,Data!J:J,">0")>=$A$1,AVERAGEIF(Data!$A:$A,"="&$A11,Data!J:J),"") | I11: =if(countifs(Data!$A:$A,"="&$A11,Data!K:K,">0")>=$A$1,AVERAGEIF(Data!$A:$A,"="&$A11,Data!K:K),"") | J11: =if(countifs(Data!$A:$A,"="&$A11,Data!L:L,">0")>=$A$1,AVERAGEIF(Data!$A:$A,"="&$A11,Data!L:L),"") | K11: =if(countifs(Data!$A:$A,"="&$A11,Data!M:M,">0")>=$A$1,AVERAGEIF(Data!$A:$A,"="&$A11,Data!M:M),"") | L11: =if(countifs(Data!$A:$A,"="&$A11,Data!N:N,">0")>=$A$1,AVERAGEIF(Data!$A:$A,"="&$A11,Data!N:N),"") | M11: =if(countifs(Data!$A:$A,"="&$A11,Data!O:O,">0")>=$A$1,AVERAGEIF(Data!$A:$A,"="&$A11,Data!O:O),"") | N11: =if(countifs(Data!$A:$A,"="&$A11,Data!P:P,">0")>=$A$1,AVERAGEIF(Data!$A:$A,"="&$A11,Data!P:P),"") | O11: =if(countifs(Data!$A:$A,"="&$A11,Data!Q:Q,">0")>=$A$1,AVERAGEIF(Data!$A:$A,"="&$A11,Data!Q:Q),"") | P11: =if(countifs(Data!$A:$A,"="&$A11,Data!R:R,">0")>=$A$1,AVERAGEIF(Data!$A:$A,"="&$A11,Data!R:R),"") | Q11: =if(countifs(Data!$A:$A,"="&$A11,Data!S:S,">0")>=$A$1,AVERAGEIF(Data!$A:$A,"="&$A11,Data!S:S),"") | R11: =if(countifs(Data!$A:$A,"="&$A11,Data!T:T,">0")>=$A$1,AVERAGEIF(Data!$A:$A,"="&$A11,Data!T:T),"") | S11: =if(countifs(Data!$A:$A,"="&$A11,Data!U:U,">0")>=$A$1,AVERAGEIF(Data!$A:$A,"="&$A11,Data!U:U),"") | T11: =if(countifs(Data!$A:$A,"="&$A11,Data!V:V,">0")>=$A$1,AVERAGEIF(Data!$A:$A,"="&$A11,Data!V:V),"")
A12: Dutch Blitz | B12: =countif(Data!A:A,"="&A12) -> 4 | C12: =if(countifs(Data!$A:$A,"="&$A12,Data!E:E,">0")>=$A$1,AVERAGEIF(Data!$A:$A,"="&$A12,Data!E:E),"") | D12: =if(countifs(Data!$A:$A,"="&$A12,Data!F:F,">0")>=$A$1,AVERAGEIF(Data!$A:$A,"="&$A12,Data!F:F),"") | E12: =if(countifs(Data!$A:$A,"="&$A12,Data!G:G,">0")>=$A$1,AVERAGEIF(Data!$A:$A,"="&$A12,Data!G:G),"") | F12: =if(countifs(Data!$A:$A,"="&$A12,Data!H:H,">0")>=$A$1,AVERAGEIF(Data!$A:$A,"="&$A12,Data!H:H),"") | G12: =if(countifs(Data!$A:$A,"="&$A12,Data!I:I,">0")>=$A$1,AVERAGEIF(Data!$A:$A,"="&$A12,Data!I:I),"") | H12: =if(countifs(Data!$A:$A,"="&$A12,Data!J:J,">0")>=$A$1,AVERAGEIF(Data!$A:$A,"="&$A12,Data!J:J),"") | I12: =if(countifs(Data!$A:$A,"="&$A12,Data!K:K,">0")>=$A$1,AVERAGEIF(Data!$A:$A,"="&$A12,Data!K:K),"") | J12: =if(countifs(Data!$A:$A,"="&$A12,Data!L:L,">0")>=$A$1,AVERAGEIF(Data!$A:$A,"="&$A12,Data!L:L),"") | K12: =if(countifs(Data!$A:$A,"="&$A12,Data!M:M,">0")>=$A$1,AVERAGEIF(Data!$A:$A,"="&$A12,Data!M:M),"") | L12: =if(countifs(Data!$A:$A,"="&$A12,Data!N:N,">0")>=$A$1,AVERAGEIF(Data!$A:$A,"="&$A12,Data!N:N),"") | M12: =if(countifs(Data!$A:$A,"="&$A12,Data!O:O,">0")>=$A$1,AVERAGEIF(Data!$A:$A,"="&$A12,Data!O:O),"") | N12: =if(countifs(Data!$A:$A,"="&$A12,Data!P:P,">0")>=$A$1,AVERAGEIF(Data!$A:$A,"="&$A12,Data!P:P),"") | O12: =if(countifs(Data!$A:$A,"="&$A12,Data!Q:Q,">0")>=$A$1,AVERAGEIF(Data!$A:$A,"="&$A12,Data!Q:Q),"") | P12: =if(countifs(Data!$A:$A,"="&$A12,Data!R:R,">0")>=$A$1,AVERAGEIF(Data!$A:$A,"="&$A12,Data!R:R),"") | Q12: =if(countifs(Data!$A:$A,"="&$A12,Data!S:S,">0")>=$A$1,AVERAGEIF(Data!$A:$A,"="&$A12,Data!S:S),"") | R12: =if(countifs(Data!$A:$A,"="&$A12,Data!T:T,">0")>=$A$1,AVERAGEIF(Data!$A:$A,"="&$A12,Data!T:T),"") | S12: =if(countifs(Data!$A:$A,"="&$A12,Data!U:U,">0")>=$A$1,AVERAGEIF(Data!$A:$A,"="&$A12,Data!U:U),"") | T12: =if(countifs(Data!$A:$A,"="&$A12,Data!V:V,">0")>=$A$1,AVERAGEIF(Data!$A:$A,"="&$A12,Data!V:V),"")
A13: Catan | B13: =countif(Data!A:A,"="&A13) -> 24 | C13: =if(countifs(Data!$A:$A,"="&$A13,Data!E:E,">0")>=$A$1,AVERAGEIF(Data!$A:$A,"="&$A13,Data!E:E),"") -> 2.1666667 | D13: =if(countifs(Data!$A:$A,"="&$A13,Data!F:F,">0")>=$A$1,AVERAGEIF(Data!$A:$A,"="&$A13,Data!F:F),"") -> 1.8695652 | E13: =if(countifs(Data!$A:$A,"="&$A13,Data!G:G,">0")>=$A$1,AVERAGEIF(Data!$A:$A,"="&$A13,Data!G:G),"") | F13: =if(countifs(Data!$A:$A,"="&$A13,Data!H:H,">0")>=$A$1,AVERAGEIF(Data!$A:$A,"="&$A13,Data!H:H),"") -> 1.7727273 | G13: =if(countifs(Data!$A:$A,"="&$A13,Data!I:I,">0")>=$A$1,AVERAGEIF(Data!$A:$A,"="&$A13,Data!I:I),"") | H13: =if(countifs(Data!$A:$A,"="&$A13,Data!J:J,">0")>=$A$1,AVERAGEIF(Data!$A:$A,"="&$A13,Data!J:J),"") | I13: =if(countifs(Data!$A:$A,"="&$A13,Data!K:K,">0")>=$A$1,AVERAGEIF(Data!$A:$A,"="&$A13,Data!K:K),"") | J13: =if(countifs(Data!$A:$A,"="&$A13,Data!L:L,">0")>=$A$1,AVERAGEIF(Data!$A:$A,"="&$A13,Data!L:L),"") | K13: =if(countifs(Data!$A:$A,"="&$A13,Data!M:M,">0")>=$A$1,AVERAGEIF(Data!$A:$A,"="&$A13,Data!M:M),"") | L13: =if(countifs(Data!$A:$A,"="&$A13,Data!N:N,">0")>=$A$1,AVERAGEIF(Data!$A:$A,"="&$A13,Data!N:N),"") | M13: =if(countifs(Data!$A:$A,"="&$A13,Data!O:O,">0")>=$A$1,AVERAGEIF(Data!$A:$A,"="&$A13,Data!O:O),"") | N13: =if(countifs(Data!$A:$A,"="&$A13,Data!P:P,">0")>=$A$1,AVERAGEIF(Data!$A:$A,"="&$A13,Data!P:P),"") | O13: =if(countifs(Data!$A:$A,"="&$A13,Data!Q:Q,">0")>=$A$1,AVERAGEIF(Data!$A:$A,"="&$A13,Data!Q:Q),"") | P13: =if(countifs(Data!$A:$A,"="&$A13,Data!R:R,">0")>=$A$1,AVERAGEIF(Data!$A:$A,"="&$A13,Data!R:R),"") | Q13: =if(countifs(Data!$A:$A,"="&$A13,Data!S:S,">0")>=$A$1,AVERAGEIF(Data!$A:$A,"="&$A13,Data!S:S),"") | R13: =if(countifs(Data!$A:$A,"="&$A13,Data!T:T,">0")>=$A$1,AVERAGEIF(Data!$A:$A,"="&$A13,Data!T:T),"") | S13: =if(countifs(Data!$A:$A,"="&$A13,Data!U:U,">0")>=$A$1,AVERAGEIF(Data!$A:$A,"="&$A13,Data!U:U),"") | T13: =if(countifs(Data!$A:$A,"="&$A13,Data!V:V,">0")>=$A$1,AVERAGEIF(Data!$A:$A,"="&$A13,Data!V:V),"")
... A22: Viticulture | B22: =countif(Data!A:A,"="&A22) -> 5 | C22: =if(countifs(Data!$A:$A,"="&$A22,Data!E:E,">0")>=$A$1,AVERAGEIF(Data!$A:$A,"="&$A22,Data!E:E),"") -> 2.6 | D22: =if(countifs(Data!$A:$A,"="&$A22,Data!F:F,">0")>=$A$1,AVERAGEIF(Data!$A:$A,"="&$A22,Data!F:F),"") -> 1.2 | E22: =if(countifs(Data!$A:$A,"="&$A22,Data!G:G,">0")>=$A$1,AVERAGEIF(Data!$A:$A,"="&$A22,Data!G:G),"") | F22: =if(countifs(Data!$A:$A,"="&$A22,Data!H:H,">0")>=$A$1,AVERAGEIF(Data!$A:$A,"="&$A22,Data!H:H),"") -> 2.2 | G22: =if(countifs(Data!$A:$A,"="&$A22,Data!I:I,">0")>=$A$1,AVERAGEIF(Data!$A:$A,"="&$A22,Data!I:I),"") | H22: =if(countifs(Data!$A:$A,"="&$A22,Data!J:J,">0")>=$A$1,AVERAGEIF(Data!$A:$A,"="&$A22,Data!J:J),"") | I22: =if(countifs(Data!$A:$A,"="&$A22,Data!K:K,">0")>=$A$1,AVERAGEIF(Data!$A:$A,"="&$A22,Data!K:K),"") | J22: =if(countifs(Data!$A:$A,"="&$A22,Data!L:L,">0")>=$A$1,AVERAGEIF(Data!$A:$A,"="&$A22,Data!L:L),"") | K22: =if(countifs(Data!$A:$A,"="&$A22,Data!M:M,">0")>=$A$1,AVERAGEIF(Data!$A:$A,"="&$A22,Data!M:M),"") | L22: =if(countifs(Data!$A:$A,"="&$A22,Data!N:N,">0")>=$A$1,AVERAGEIF(Data!$A:$A,"="&$A22,Data!N:N),"") | M22: =if(countifs(Data!$A:$A,"="&$A22,Data!O:O,">0")>=$A$1,AVERAGEIF(Data!$A:$A,"="&$A22,Data!O:O),"") | N22: =if(countifs(Data!$A:$A,"="&$A22,Data!P:P,">0")>=$A$1,AVERAGEIF(Data!$A:$A,"="&$A22,Data!P:P),"") | O22: =if(countifs(Data!$A:$A,"="&$A22,Data!Q:Q,">0")>=$A$1,AVERAGEIF(Data!$A:$A,"="&$A22,Data!Q:Q),"") | P22: =if(countifs(Data!$A:$A,"="&$A22,Data!R:R,">0")>=$A$1,AVERAGEIF(Data!$A:$A,"="&$A22,Data!R:R),"") | Q22: =if(countifs(Data!$A:$A,"="&$A22,Data!S:S,">0")>=$A$1,AVERAGEIF(Data!$A:$A,"="&$A22,Data!S:S),"") | R22: =if(countifs(Data!$A:$A,"="&$A22,Data!T:T,">0")>=$A$1,AVERAGEIF(Data!$A:$A,"="&$A22,Data!T:T),"") | S22: =if(countifs(Data!$A:$A,"="&$A22,Data!U:U,">0")>=$A$1,AVERAGEIF(Data!$A:$A,"="&$A22,Data!U:U),"") | T22: =if(countifs(Data!$A:$A,"="&$A22,Data!V:V,">0")>=$A$1,AVERAGEIF(Data!$A:$A,"="&$A22,Data!V:V),"")
C23: =AVERAGE(Data!E:E) -> 2.107084 | D23: =AVERAGE(Data!F:F) -> 1.9799331 | E23: =AVERAGE(Data!G:G) -> 2.0977918 | F23: =AVERAGE(Data!H:H) -> 2.2261484 | G23: =AVERAGE(Data!I:I) -> 2.8333333 | H23: =AVERAGE(Data!J:J) -> 3 | I23: =AVERAGE(Data!K:K) -> 2.3703704 | J23: =AVERAGE(Data!L:L) -> 2.8888889 | K23: =AVERAGE(Data!M:M) -> 2.3333333 | L23: =AVERAGE(Data!N:N) -> 3.25 | M23: =AVERAGE(Data!O:O) -> 4 | N23: =AVERAGE(Data!P:P) -> 1 | O23: =AVERAGE(Data!Q:Q) -> 2 | P23: =AVERAGE(Data!R:R) -> 2.6666667 | Q23: =AVERAGE(Data!S:S) -> 3.6666667 | R23: =AVERAGE(Data!T:T) -> 4 | S23: =AVERAGE(Data!U:U) -> 2 | T23: =AVERAGE(Data!V:V) -> 2.76
A25: Odds Against Any Opponent | C25: =(sumifs(Data!$D:$D,Data!E:E,"<>")-SUMIFS(Data!E:E,Data!E:E,"<>"))/(SUMIFS(Data!$D:$D,Data!E:E,"<>")-COUNTIFS(Data!E:E,">0")) -> 0.49775785 | D25: =(sumifs(Data!$D:$D,Data!F:F,"<>")-SUMIFS(Data!F:F,Data!F:F,"<>"))/(SUMIFS(Data!$D:$D,Data!F:F,"<>")-COUNTIFS(Data!F:F,">0")) -> 0.55572403 | E25: =(sumifs(Data!$D:$D,Data!G:G,"<>")-SUMIFS(Data!G:G,Data!G:G,"<>"))/(SUMIFS(Data!$D:$D,Data!G:G,"<>")-COUNTIFS(Data!G:G,">0")) -> 0.50214592 | F25: =(sumifs(Data!$D:$D,Data!H:H,"<>")-SUMIFS(Data!H:H,Data!H:H,"<>"))/(SUMIFS(Data!$D:$D,Data!H:H,"<>")-COUNTIFS(Data!H:H,">0")) -> 0.45696401 | G25: =(sumifs(Data!$D:$D,Data!I:I,"<>")-SUMIFS(Data!I:I,Data!I:I,"<>"))/(SUMIFS(Data!$D:$D,Data!I:I,"<>")-COUNTIFS(Data!I:I,">0")) -> 0.36538462 | H25: =(sumifs(Data!$D:$D,Data!J:J,"<>")-SUMIFS(Data!J:J,Data!J:J,"<>"))/(SUMIFS(Data!$D:$D,Data!J:J,"<>")-COUNTIFS(Data!J:J,">0")) -> 0.34146341 | I25: =(sumifs(Data!$D:$D,Data!K:K,"<>")-SUMIFS(Data!K:K,Data!K:K,"<>"))/(SUMIFS(Data!$D:$D,Data!K:K,"<>")-COUNTIFS(Data!K:K,">0")) -> 0.48611111 | J25: =(sumifs(Data!$D:$D,Data!L:L,"<>")-SUMIFS(Data!L:L,Data!L:L,"<>"))/(SUMIFS(Data!$D:$D,Data!L:L,"<>")-COUNTIFS(Data!L:L,">0")) -> 0.39285714 | K25: =(sumifs(Data!$D:$D,Data!M:M,"<>")-SUMIFS(Data!M:M,Data!M:M,"<>"))/(SUMIFS(Data!$D:$D,Data!M:M,"<>")-COUNTIFS(Data!M:M,">0")) -> 0.5 | L25: =(sumifs(Data!$D:$D,Data!N:N,"<>")-SUMIFS(Data!N:N,Data!N:N,"<>"))/(SUMIFS(Data!$D:$D,Data!N:N,"<>")-COUNTIFS(Data!N:N,">0")) -> 0.18181818 | M25: =(sumifs(Data!$D:$D,Data!O:O,"<>")-SUMIFS(Data!O:O,Data!O:O,"<>"))/(SUMIFS(Data!$D:$D,Data!O:O,"<>")-COUNTIFS(Data!O:O,">0")) -> 0 | N25: =(sumifs(Data!$D:$D,Data!P:P,"<>")-SUMIFS(Data!P:P,Data!P:P,"<>"))/(SUMIFS(Data!$D:$D,Data!P:P,"<>")-COUNTIFS(Data!P:P,">0")) -> 1 | O25: =(sumifs(Data!$D:$D,Data!Q:Q,"<>")-SUMIFS(Data!Q:Q,Data!Q:Q,"<>"))/(SUMIFS(Data!$D:$D,Data!Q:Q,"<>")-COUNTIFS(Data!Q:Q,">0")) -> 0.5 | P25: =(sumifs(Data!$D:$D,Data!R:R,"<>")-SUMIFS(Data!R:R,Data!R:R,"<>"))/(SUMIFS(Data!$D:$D,Data!R:R,"<>")-COUNTIFS(Data!R:R,">0")) -> 0.375 | Q25: =(sumifs(Data!$D:$D,Data!S:S,"<>")-SUMIFS(Data!S:S,Data!S:S,"<>"))/(SUMIFS(Data!$D:$D,Data!S:S,"<>")-COUNTIFS(Data!S:S,">0")) -> 0.11111111 | R25: =(sumifs(Data!$D:$D,Data!T:T,"<>")-SUMIFS(Data!T:T,Data!T:T,"<>"))/(SUMIFS(Data!$D:$D,Data!T:T,"<>")-COUNTIFS(Data!T:T,">0")) -> 0 | S25: =(sumifs(Data!$D:$D,Data!U:U,"<>")-SUMIFS(Data!U:U,Data!U:U,"<>"))/(SUMIFS(Data!$D:$D,Data!U:U,"<>")-COUNTIFS(Data!U:U,">0")) -> 0.66666667 | T25: =(sumifs(Data!$D:$D,Data!V:V,"<>")-SUMIFS(Data!V:V,Data!V:V,"<>"))/(SUMIFS(Data!$D:$D,Data!V:V,"<>")-COUNTIFS(Data!V:V,">0")) -> 0.40540541

Sheet Odds
B1: Count | C1: =Data!E1 -> Jeffrey | D1: =Data!F1 -> Robert | E1: =Data!G1 -> Bobby | F1: =Data!H1 -> Stephen | G1: =Data!I1 -> Cory | H1: =Data!J1 -> Chelsea | I1: =Data!K1 -> Robin | J1: =Data!L1 -> Marcus | ... T1: =Data!V1 -> Abby
A2: Carcassonne | B2: =countif(Data!A:A,"="&A2) -> 24 | C2: =if(COUNTIFS(Data!E:E,"<>",Data!$A:$A,$A2,Data!$D:$D,$B$30)<$B$31,"",(sumifs(Data!$D:$D,Data!E:E,"<>",Data!$A:$A,$A2,Data!$D:$D,$B$30)-sumifs(Data!E:E,Data!E:E,"<>",Data!$A:$A,$A2,Data!$D:$D,$B$30))/(sumifs(Data!$D:$D,Data!E:E,"<>",Data!$A:$A,$A2,Data!$D:$D,$B$30)-countifs(Data!E:E,"<>",Data!$A:$A,$A2,Data!$D:$D,$B$30))) -> 0.53125 | D2: =if(COUNTIFS(Data!F:F,"<>",Data!$A:$A,$A2,Data!$D:$D,$B$30)<$B$31,"",(sumifs(Data!$D:$D,Data!F:F,"<>",Data!$A:$A,$A2,Data!$D:$D,$B$30)-sumifs(Data!F:F,Data!F:F,"<>",Data!$A:$A,$A2,Data!$D:$D,$B$30))/(sumifs(Data!$D:$D,Data!F:F,"<>",Data!$A:$A,$A2,Data!$D:$D,$B$30)-countifs(Data!F:F,"<>",Data!$A:$A,$A2,Data!$D:$D,$B$30))) -> 0.59375 | E2: =if(COUNTIFS(Data!G:G,"<>",Data!$A:$A,$A2,Data!$D:$D,$B$30)<$B$31,"",(sumifs(Data!$D:$D,Data!G:G,"<>",Data!$A:$A,$A2,Data!$D:$D,$B$30)-sumifs(Data!G:G,Data!G:G,"<>",Data!$A:$A,$A2,Data!$D:$D,$B$30))/(sumifs(Data!$D:$D,Data!G:G,"<>",Data!$A:$A,$A2,Data!$D:$D,$B$30)-countifs(Data!G:G,"<>",Data!$A:$A,$A2,Data!$D:$D,$B$30))) | F2: =if(COUNTIFS(Data!H:H,"<>",Data!$A:$A,$A2,Data!$D:$D,$B$30)<$B$31,"",(sumifs(Data!$D:$D,Data!H:H,"<>",Data!$A:$A,$A2,Data!$D:$D,$B$30)-sumifs(Data!H:H,Data!H:H,"<>",Data!$A:$A,$A2,Data!$D:$D,$B$30))/(sumifs(Data!$D:$D,Data!H:H,"<>",Data!$A:$A,$A2,Data!$D:$D,$B$30)-countifs(Data!H:H,"<>",Data!$A:$A,$A2,Data!$D:$D,$B$30))) -> 0.36363636 | G2: =if(COUNTIFS(Data!I:I,"<>",Data!$A:$A,$A2,Data!$D:$D,$B$30)<$B$31,"",(sumifs(Data!$D:$D,Data!I:I,"<>",Data!$A:$A,$A2,Data!$D:$D,$B$30)-sumifs(Data!I:I,Data!I:I,"<>",Data!$A:$A,$A2,Data!$D:$D,$B$30))/(sumifs(Data!$D:$D,Data!I:I,"<>",Data!$A:$A,$A2,Data!$D:$D,$B$30)-countifs(Data!I:I,"<>",Data!$A:$A,$A2,Data!$D:$D,$B$30))) | H2: =if(COUNTIFS(Data!J:J,"<>",Data!$A:$A,$A2,Data!$D:$D,$B$30)<$B$31,"",(sumifs(Data!$D:$D,Data!J:J,"<>",Data!$A:$A,$A2,Data!$D:$D,$B$30)-sumifs(Data!J:J,Data!J:J,"<>",Data!$A:$A,$A2,Data!$D:$D,$B$30))/(sumifs(Data!$D:$D,Data!J:J,"<>",Data!$A:$A,$A2,Data!$D:$D,$B$30)-countifs(Data!J:J,"<>",Data!$A:$A,$A2,Data!$D:$D,$B$30))) | I2: =if(COUNTIFS(Data!K:K,"<>",Data!$A:$A,$A2,Data!$D:$D,$B$30)<$B$31,"",(sumifs(Data!$D:$D,Data!K:K,"<>",Data!$A:$A,$A2,Data!$D:$D,$B$30)-sumifs(Data!K:K,Data!K:K,"<>",Data!$A:$A,$A2,Data!$D:$D,$B$30))/(sumifs(Data!$D:$D,Data!K:K,"<>",Data!$A:$A,$A2,Data!$D:$D,$B$30)-countifs(Data!K:K,"<>",Data!$A:$A,$A2,Data!$D:$D,$B$30))) | J2: =if(COUNTIFS(Data!L:L,"<>",Data!$A:$A,$A2,Data!$D:$D,$B$30)<$B$31,"",(sumifs(Data!$D:$D,Data!L:L,"<>",Data!$A:$A,$A2,Data!$D:$D,$B$30)-sumifs(Data!L:L,Data!L:L,"<>",Data!$A:$A,$A2,Data!$D:$D,$B$30))/(sumifs(Data!$D:$D,Data!L:L,"<>",Data!$A:$A,$A2,Data!$D:$D,$B$30)-countifs(Data!L:L,"<>",Data!$A:$A,$A2,Data!$D:$D,$B$30))) | K2: =if(COUNTIFS(Data!M:M,"<>",Data!$A:$A,$A2,Data!$D:$D,$B$30)<$B$31,"",(sumifs(Data!$D:$D,Data!M:M,"<>",Data!$A:$A,$A2,Data!$D:$D,$B$30)-sumifs(Data!M:M,Data!M:M,"<>",Data!$A:$A,$A2,Data!$D:$D,$B$30))/(sumifs(Data!$D:$D,Data!M:M,"<>",Data!$A:$A,$A2,Data!$D:$D,$B$30)-countifs(Data!M:M,"<>",Data!$A:$A,$A2,Data!$D:$D,$B$30))) | L2: =if(COUNTIFS(Data!N:N,"<>",Data!$A:$A,$A2,Data!$D:$D,$B$30)<$B$31,"",(sumifs(Data!$D:$D,Data!N:N,"<>",Data!$A:$A,$A2,Data!$D:$D,$B$30)-sumifs(Data!N:N,Data!N:N,"<>",Data!$A:$A,$A2,Data!$D:$D,$B$30))/(sumifs(Data!$D:$D,Data!N:N,"<>",Data!$A:$A,$A2,Data!$D:$D,$B$30)-countifs(Data!N:N,"<>",Data!$A:$A,$A2,Data!$D:$D,$B$30))) | M2: =if(COUNTIFS(Data!O:O,"<>",Data!$A:$A,$A2,Data!$D:$D,$B$30)<$B$31,"",(sumifs(Data!$D:$D,Data!O:O,"<>",Data!$A:$A,$A2,Data!$D:$D,$B$30)-sumifs(Data!O:O,Data!O:O,"<>",Data!$A:$A,$A2,Data!$D:$D,$B$30))/(sumifs(Data!$D:$D,Data!O:O,"<>",Data!$A:$A,$A2,Data!$D:$D,$B$30)-countifs(Data!O:O,"<>",Data!$A:$A,$A2,Data!$D:$D,$B$30))) | N2: =if(COUNTIFS(Data!P:P,"<>",Data!$A:$A,$A2,Data!$D:$D,$B$30)<$B$31,"",(sumifs(Data!$D:$D,Data!P:P,"<>",Data!$A:$A,$A2,Data!$D:$D,$B$30)-sumifs(Data!P:P,Data!P:P,"<>",Data!$A:$A,$A2,Data!$D:$D,$B$30))/(sumifs(Data!$D:$D,Data!P:P,"<>",Data!$A:$A,$A2,Data!$D:$D,$B$30)-countifs(Data!P:P,"<>",Data!$A:$A,$A2,Data!$D:$D,$B$30))) | O2: =if(COUNTIFS(Data!Q:Q,"<>",Data!$A:$A,$A2,Data!$D:$D,$B$30)<$B$31,"",(sumifs(Data!$D:$D,Data!Q:Q,"<>",Data!$A:$A,$A2,Data!$D:$D,$B$30)-sumifs(Data!Q:Q,Data!Q:Q,"<>",Data!$A:$A,$A2,Data!$D:$D,$B$30))/(sumifs(Data!$D:$D,Data!Q:Q,"<>",Data!$A:$A,$A2,Data!$D:$D,$B$30)-countifs(Data!Q:Q,"<>",Data!$A:$A,$A2,Data!$D:$D,$B$30))) | P2: =if(COUNTIFS(Data!R:R,"<>",Data!$A:$A,$A2,Data!$D:$D,$B$30)<$B$31,"",(sumifs(Data!$D:$D,Data!R:R,"<>",Data!$A:$A,$A2,Data!$D:$D,$B$30)-sumifs(Data!R:R,Data!R:R,"<>",Data!$A:$A,$A2,Data!$D:$D,$B$30))/(sumifs(Data!$D:$D,Data!R:R,"<>",Data!$A:$A,$A2,Data!$D:$D,$B$30)-countifs(Data!R:R,"<>",Data!$A:$A,$A2,Data!$D:$D,$B$30))) | Q2: =if(COUNTIFS(Data!S:S,"<>",Data!$A:$A,$A2,Data!$D:$D,$B$30)<$B$31,"",(sumifs(Data!$D:$D,Data!S:S,"<>",Data!$A:$A,$A2,Data!$D:$D,$B$30)-sumifs(Data!S:S,Data!S:S,"<>",Data!$A:$A,$A2,Data!$D:$D,$B$30))/(sumifs(Data!$D:$D,Data!S:S,"<>",Data!$A:$A,$A2,Data!$D:$D,$B$30)-countifs(Data!S:S,"<>",Data!$A:$A,$A2,Data!$D:$D,$B$30))) | R2: =if(COUNTIFS(Data!T:T,"<>",Data!$A:$A,$A2,Data!$D:$D,$B$30)<$B$31,"",(sumifs(Data!$D:$D,Data!T:T,"<>",Data!$A:$A,$A2,Data!$D:$D,$B$30)-sumifs(Data!T:T,Data!T:T,"<>",Data!$A:$A,$A2,Data!$D:$D,$B$30))/(sumifs(Data!$D:$D,Data!T:T,"<>",Data!$A:$A,$A2,Data!$D:$D,$B$30)-countifs(Data!T:T,"<>",Data!$A:$A,$A2,Data!$D:$D,$B$30))) | S2: =if(COUNTIFS(Data!U:U,"<>",Data!$A:$A,$A2,Data!$D:$D,$B$30)<$B$31,"",(sumifs(Data!$D:$D,Data!U:U,"<>",Data!$A:$A,$A2,Data!$D:$D,$B$30)-sumifs(Data!U:U,Data!U:U,"<>",Data!$A:$A,$A2,Data!$D:$D,$B$30))/(sumifs(Data!$D:$D,Data!U:U,"<>",Data!$A:$A,$A2,Data!$D:$D,$B$30)-countifs(Data!U:U,"<>",Data!$A:$A,$A2,Data!$D:$D,$B$30))) | T2: =if(COUNTIFS(Data!V:V,"<>",Data!$A:$A,$A2,Data!$D:$D,$B$30)<$B$31,"",(sumifs(Data!$D:$D,Data!V:V,"<>",Data!$A:$A,$A2,Data!$D:$D,$B$30)-sumifs(Data!V:V,Data!V:V,"<>",Data!$A:$A,$A2,Data!$D:$D,$B$30))/(sumifs(Data!$D:$D,Data!V:V,"<>",Data!$A:$A,$A2,Data!$D:$D,$B$30)-countifs(Data!V:V,"<>",Data!$A:$A,$A2,Data!$D:$D,$B$30)))
A3: Dominion | B3: =countif(Data!A:A,"="&A3) -> 3 | C3: =if(COUNTIFS(Data!E:E,"<>",Data!$A:$A,$A3,Data!$D:$D,$B$30)<$B$31,"",(sumifs(Data!$D:$D,Data!E:E,"<>",Data!$A:$A,$A3,Data!$D:$D,$B$30)-sumifs(Data!E:E,Data!E:E,"<>",Data!$A:$A,$A3,Data!$D:$D,$B$30))/(sumifs(Data!$D:$D,Data!E:E,"<>",Data!$A:$A,$A3,Data!$D:$D,$B$30)-countifs(Data!E:E,"<>",Data!$A:$A,$A3,Data!$D:$D,$B$30))) | D3: =if(COUNTIFS(Data!F:F,"<>",Data!$A:$A,$A3,Data!$D:$D,$B$30)<$B$31,"",(sumifs(Data!$D:$D,Data!F:F,"<>",Data!$A:$A,$A3,Data!$D:$D,$B$30)-sumifs(Data!F:F,Data!F:F,"<>",Data!$A:$A,$A3,Data!$D:$D,$B$30))/(sumifs(Data!$D:$D,Data!F:F,"<>",Data!$A:$A,$A3,Data!$D:$D,$B$30)-countifs(Data!F:F,"<>",Data!$A:$A,$A3,Data!$D:$D,$B$30))) | E3: =if(COUNTIFS(Data!G:G,"<>",Data!$A:$A,$A3,Data!$D:$D,$B$30)<$B$31,"",(sumifs(Data!$D:$D,Data!G:G,"<>",Data!$A:$A,$A3,Data!$D:$D,$B$30)-sumifs(Data!G:G,Data!G:G,"<>",Data!$A:$A,$A3,Data!$D:$D,$B$30))/(sumifs(Data!$D:$D,Data!G:G,"<>",Data!$A:$A,$A3,Data!$D:$D,$B$30)-countifs(Data!G:G,"<>",Data!$A:$A,$A3,Data!$D:$D,$B$30))) | F3: =if(COUNTIFS(Data!H:H,"<>",Data!$A:$A,$A3,Data!$D:$D,$B$30)<$B$31,"",(sumifs(Data!$D:$D,Data!H:H,"<>",Data!$A:$A,$A3,Data!$D:$D,$B$30)-sumifs(Data!H:H,Data!H:H,"<>",Data!$A:$A,$A3,Data!$D:$D,$B$30))/(sumifs(Data!$D:$D,Data!H:H,"<>",Data!$A:$A,$A3,Data!$D:$D,$B$30)-countifs(Data!H:H,"<>",Data!$A:$A,$A3,Data!$D:$D,$B$30))) | G3: =if(COUNTIFS(Data!I:I,"<>",Data!$A:$A,$A3,Data!$D:$D,$B$30)<$B$31,"",(sumifs(Data!$D:$D,Data!I:I,"<>",Data!$A:$A,$A3,Data!$D:$D,$B$30)-sumifs(Data!I:I,Data!I:I,"<>",Data!$A:$A,$A3,Data!$D:$D,$B$30))/(sumifs(Data!$D:$D,Data!I:I,"<>",Data!$A:$A,$A3,Data!$D:$D,$B$30)-countifs(Data!I:I,"<>",Data!$A:$A,$A3,Data!$D:$D,$B$30))) | H3: =if(COUNTIFS(Data!J:J,"<>",Data!$A:$A,$A3,Data!$D:$D,$B$30)<$B$31,"",(sumifs(Data!$D:$D,Data!J:J,"<>",Data!$A:$A,$A3,Data!$D:$D,$B$30)-sumifs(Data!J:J,Data!J:J,"<>",Data!$A:$A,$A3,Data!$D:$D,$B$30))/(sumifs(Data!$D:$D,Data!J:J,"<>",Data!$A:$A,$A3,Data!$D:$D,$B$30)-countifs(Data!J:J,"<>",Data!$A:$A,$A3,Data!$D:$D,$B$30))) | I3: =if(COUNTIFS(Data!K:K,"<>",Data!$A:$A,$A3,Data!$D:$D,$B$30)<$B$31,"",(sumifs(Data!$D:$D,Data!K:K,"<>",Data!$A:$A,$A3,Data!$D:$D,$B$30)-sumifs(Data!K:K,Data!K:K,"<>",Data!$A:$A,$A3,Data!$D:$D,$B$30))/(sumifs(Data!$D:$D,Data!K:K,"<>",Data!$A:$A,$A3,Data!$D:$D,$B$30)-countifs(Data!K:K,"<>",Data!$A:$A,$A3,Data!$D:$D,$B$30))) | J3: =if(COUNTIFS(Data!L:L,"<>",Data!$A:$A,$A3,Data!$D:$D,$B$30)<$B$31,"",(sumifs(Data!$D:$D,Data!L:L,"<>",Data!$A:$A,$A3,Data!$D:$D,$B$30)-sumifs(Data!L:L,Data!L:L,"<>",Data!$A:$A,$A3,Data!$D:$D,$B$30))/(sumifs(Data!$D:$D,Data!L:L,"<>",Data!$A:$A,$A3,Data!$D:$D,$B$30)-countifs(Data!L:L,"<>",Data!$A:$A,$A3,Data!$D:$D,$B$30))) | K3: =if(COUNTIFS(Data!M:M,"<>",Data!$A:$A,$A3,Data!$D:$D,$B$30)<$B$31,"",(sumifs(Data!$D:$D,Data!M:M,"<>",Data!$A:$A,$A3,Data!$D:$D,$B$30)-sumifs(Data!M:M,Data!M:M,"<>",Data!$A:$A,$A3,Data!$D:$D,$B$30))/(sumifs(Data!$D:$D,Data!M:M,"<>",Data!$A:$A,$A3,Data!$D:$D,$B$30)-countifs(Data!M:M,"<>",Data!$A:$A,$A3,Data!$D:$D,$B$30))) | L3: =if(COUNTIFS(Data!N:N,"<>",Data!$A:$A,$A3,Data!$D:$D,$B$30)<$B$31,"",(sumifs(Data!$D:$D,Data!N:N,"<>",Data!$A:$A,$A3,Data!$D:$D,$B$30)-sumifs(Data!N:N,Data!N:N,"<>",Data!$A:$A,$A3,Data!$D:$D,$B$30))/(sumifs(Data!$D:$D,Data!N:N,"<>",Data!$A:$A,$A3,Data!$D:$D,$B$30)-countifs(Data!N:N,"<>",Data!$A:$A,$A3,Data!$D:$D,$B$30))) | M3: =if(COUNTIFS(Data!O:O,"<>",Data!$A:$A,$A3,Data!$D:$D,$B$30)<$B$31,"",(sumifs(Data!$D:$D,Data!O:O,"<>",Data!$A:$A,$A3,Data!$D:$D,$B$30)-sumifs(Data!O:O,Data!O:O,"<>",Data!$A:$A,$A3,Data!$D:$D,$B$30))/(sumifs(Data!$D:$D,Data!O:O,"<>",Data!$A:$A,$A3,Data!$D:$D,$B$30)-countifs(Data!O:O,"<>",Data!$A:$A,$A3,Data!$D:$D,$B$30))) | N3: =if(COUNTIFS(Data!P:P,"<>",Data!$A:$A,$A3,Data!$D:$D,$B$30)<$B$31,"",(sumifs(Data!$D:$D,Data!P:P,"<>",Data!$A:$A,$A3,Data!$D:$D,$B$30)-sumifs(Data!P:P,Data!P:P,"<>",Data!$A:$A,$A3,Data!$D:$D,$B$30))/(sumifs(Data!$D:$D,Data!P:P,"<>",Data!$A:$A,$A3,Data!$D:$D,$B$30)-countifs(Data!P:P,"<>",Data!$A:$A,$A3,Data!$D:$D,$B$30))) | O3: =if(COUNTIFS(Data!Q:Q,"<>",Data!$A:$A,$A3,Data!$D:$D,$B$30)<$B$31,"",(sumifs(Data!$D:$D,Data!Q:Q,"<>",Data!$A:$A,$A3,Data!$D:$D,$B$30)-sumifs(Data!Q:Q,Data!Q:Q,"<>",Data!$A:$A,$A3,Data!$D:$D,$B$30))/(sumifs(Data!$D:$D,Data!Q:Q,"<>",Data!$A:$A,$A3,Data!$D:$D,$B$30)-countifs(Data!Q:Q,"<>",Data!$A:$A,$A3,Data!$D:$D,$B$30))) | P3: =if(COUNTIFS(Data!R:R,"<>",Data!$A:$A,$A3,Data!$D:$D,$B$30)<$B$31,"",(sumifs(Data!$D:$D,Data!R:R,"<>",Data!$A:$A,$A3,Data!$D:$D,$B$30)-sumifs(Data!R:R,Data!R:R,"<>",Data!$A:$A,$A3,Data!$D:$D,$B$30))/(sumifs(Data!$D:$D,Data!R:R,"<>",Data!$A:$A,$A3,Data!$D:$D,$B$30)-countifs(Data!R:R,"<>",Data!$A:$A,$A3,Data!$D:$D,$B$30))) | Q3: =if(COUNTIFS(Data!S:S,"<>",Data!$A:$A,$A3,Data!$D:$D,$B$30)<$B$31,"",(sumifs(Data!$D:$D,Data!S:S,"<>",Data!$A:$A,$A3,Data!$D:$D,$B$30)-sumifs(Data!S:S,Data!S:S,"<>",Data!$A:$A,$A3,Data!$D:$D,$B$30))/(sumifs(Data!$D:$D,Data!S:S,"<>",Data!$A:$A,$A3,Data!$D:$D,$B$30)-countifs(Data!S:S,"<>",Data!$A:$A,$A3,Data!$D:$D,$B$30))) | R3: =if(COUNTIFS(Data!T:T,"<>",Data!$A:$A,$A3,Data!$D:$D,$B$30)<$B$31,"",(sumifs(Data!$D:$D,Data!T:T,"<>",Data!$A:$A,$A3,Data!$D:$D,$B$30)-sumifs(Data!T:T,Data!T:T,"<>",Data!$A:$A,$A3,Data!$D:$D,$B$30))/(sumifs(Data!$D:$D,Data!T:T,"<>",Data!$A:$A,$A3,Data!$D:$D,$B$30)-countifs(Data!T:T,"<>",Data!$A:$A,$A3,Data!$D:$D,$B$30))) | S3: =if(COUNTIFS(Data!U:U,"<>",Data!$A:$A,$A3,Data!$D:$D,$B$30)<$B$31,"",(sumifs(Data!$D:$D,Data!U:U,"<>",Data!$A:$A,$A3,Data!$D:$D,$B$30)-sumifs(Data!U:U,Data!U:U,"<>",Data!$A:$A,$A3,Data!$D:$D,$B$30))/(sumifs(Data!$D:$D,Data!U:U,"<>",Data!$A:$A,$A3,Data!$D:$D,$B$30)-countifs(Data!U:U,"<>",Data!$A:$A,$A3,Data!$D:$D,$B$30))) | T3: =if(COUNTIFS(Data!V:V,"<>",Data!$A:$A,$A3,Data!$D:$D,$B$30)<$B$31,"",(sumifs(Data!$D:$D,Data!V:V,"<>",Data!$A:$A,$A3,Data!$D:$D,$B$30)-sumifs(Data!V:V,Data!V:V,"<>",Data!$A:$A,$A3,Data!$D:$D,$B$30))/(sumifs(Data!$D:$D,Data!V:V,"<>",Data!$A:$A,$A3,Data!$D:$D,$B$30)-countifs(Data!V:V,"<>",Data!$A:$A,$A3,Data!$D:$D,$B$30)))
A4: King of New York | B4: =countif(Data!A:A,"="&A4) -> 57 | C4: =if(COUNTIFS(Data!E:E,"<>",Data!$A:$A,$A4,Data!$D:$D,$B$30)<$B$31,"",(sumifs(Data!$D:$D,Data!E:E,"<>",Data!$A:$A,$A4,Data!$D:$D,$B$30)-sumifs(Data!E:E,Data!E:E,"<>",Data!$A:$A,$A4,Data!$D:$D,$B$30))/(sumifs(Data!$D:$D,Data!E:E,"<>",Data!$A:$A,$A4,Data!$D:$D,$B$30)-countifs(Data!E:E,"<>",Data!$A:$A,$A4,Data!$D:$D,$B$30))) -> 0.5 | D4: =if(COUNTIFS(Data!F:F,"<>",Data!$A:$A,$A4,Data!$D:$D,$B$30)<$B$31,"",(sumifs(Data!$D:$D,Data!F:F,"<>",Data!$A:$A,$A4,Data!$D:$D,$B$30)-sumifs(Data!F:F,Data!F:F,"<>",Data!$A:$A,$A4,Data!$D:$D,$B$30))/(sumifs(Data!$D:$D,Data!F:F,"<>",Data!$A:$A,$A4,Data!$D:$D,$B$30)-countifs(Data!F:F,"<>",Data!$A:$A,$A4,Data!$D:$D,$B$30))) -> 0.53191489 | E4: =if(COUNTIFS(Data!G:G,"<>",Data!$A:$A,$A4,Data!$D:$D,$B$30)<$B$31,"",(sumifs(Data!$D:$D,Data!G:G,"<>",Data!$A:$A,$A4,Data!$D:$D,$B$30)-sumifs(Data!G:G,Data!G:G,"<>",Data!$A:$A,$A4,Data!$D:$D,$B$30))/(sumifs(Data!$D:$D,Data!G:G,"<>",Data!$A:$A,$A4,Data!$D:$D,$B$30)-countifs(Data!G:G,"<>",Data!$A:$A,$A4,Data!$D:$D,$B$30))) | F4: =if(COUNTIFS(Data!H:H,"<>",Data!$A:$A,$A4,Data!$D:$D,$B$30)<$B$31,"",(sumifs(Data!$D:$D,Data!H:H,"<>",Data!$A:$A,$A4,Data!$D:$D,$B$30)-sumifs(Data!H:H,Data!H:H,"<>",Data!$A:$A,$A4,Data!$D:$D,$B$30))/(sumifs(Data!$D:$D,Data!H:H,"<>",Data!$A:$A,$A4,Data!$D:$D,$B$30)-countifs(Data!H:H,"<>",Data!$A:$A,$A4,Data!$D:$D,$B$30))) -> 0.46875 | G4: =if(COUNTIFS(Data!I:I,"<>",Data!$A:$A,$A4,Data!$D:$D,$B$30)<$B$31,"",(sumifs(Data!$D:$D,Data!I:I,"<>",Data!$A:$A,$A4,Data!$D:$D,$B$30)-sumifs(Data!I:I,Data!I:I,"<>",Data!$A:$A,$A4,Data!$D:$D,$B$30))/(sumifs(Data!$D:$D,Data!I:I,"<>",Data!$A:$A,$A4,Data!$D:$D,$B$30)-countifs(Data!I:I,"<>",Data!$A:$A,$A4,Data!$D:$D,$B$30))) | H4: =if(COUNTIFS(Data!J:J,"<>",Data!$A:$A,$A4,Data!$D:$D,$B$30)<$B$31,"",(sumifs(Data!$D:$D,Data!J:J,"<>",Data!$A:$A,$A4,Data!$D:$D,$B$30)-sumifs(Data!J:J,Data!J:J,"<>",Data!$A:$A,$A4,Data!$D:$D,$B$30))/(sumifs(Data!$D:$D,Data!J:J,"<>",Data!$A:$A,$A4,Data!$D:$D,$B$30)-countifs(Data!J:J,"<>",Data!$A:$A,$A4,Data!$D:$D,$B$30))) | I4: =if(COUNTIFS(Data!K:K,"<>",Data!$A:$A,$A4,Data!$D:$D,$B$30)<$B$31,"",(sumifs(Data!$D:$D,Data!K:K,"<>",Data!$A:$A,$A4,Data!$D:$D,$B$30)-sumifs(Data!K:K,Data!K:K,"<>",Data!$A:$A,$A4,Data!$D:$D,$B$30))/(sumifs(Data!$D:$D,Data!K:K,"<>",Data!$A:$A,$A4,Data!$D:$D,$B$30)-countifs(Data!K:K,"<>",Data!$A:$A,$A4,Data!$D:$D,$B$30))) | J4: =if(COUNTIFS(Data!L:L,"<>",Data!$A:$A,$A4,Data!$D:$D,$B$30)<$B$31,"",(sumifs(Data!$D:$D,Data!L:L,"<>",Data!$A:$A,$A4,Data!$D:$D,$B$30)-sumifs(Data!L:L,Data!L:L,"<>",Data!$A:$A,$A4,Data!$D:$D,$B$30))/(sumifs(Data!$D:$D,Data!L:L,"<>",Data!$A:$A,$A4,Data!$D:$D,$B$30)-countifs(Data!L:L,"<>",Data!$A:$A,$A4,Data!$D:$D,$B$30))) | K4: =if(COUNTIFS(Data!M:M,"<>",Data!$A:$A,$A4,Data!$D:$D,$B$30)<$B$31,"",(sumifs(Data!$D:$D,Data!M:M,"<>",Data!$A:$A,$A4,Data!$D:$D,$B$30)-sumifs(Data!M:M,Data!M:M,"<>",Data!$A:$A,$A4,Data!$D:$D,$B$30))/(sumifs(Data!$D:$D,Data!M:M,"<>",Data!$A:$A,$A4,Data!$D:$D,$B$30)-countifs(Data!M:M,"<>",Data!$A:$A,$A4,Data!$D:$D,$B$30))) | L4: =if(COUNTIFS(Data!N:N,"<>",Data!$A:$A,$A4,Data!$D:$D,$B$30)<$B$31,"",(sumifs(Data!$D:$D,Data!N:N,"<>",Data!$A:$A,$A4,Data!$D:$D,$B$30)-sumifs(Data!N:N,Data!N:N,"<>",Data!$A:$A,$A4,Data!$D:$D,$B$30))/(sumifs(Data!$D:$D,Data!N:N,"<>",Data!$A:$A,$A4,Data!$D:$D,$B$30)-countifs(Data!N:N,"<>",Data!$A:$A,$A4,Data!$D:$D,$B$30))) | M4: =if(COUNTIFS(Data!O:O,"<>",Data!$A:$A,$A4,Data!$D:$D,$B$30)<$B$31,"",(sumifs(Data!$D:$D,Data!O:O,"<>",Data!$A:$A,$A4,Data!$D:$D,$B$30)-sumifs(Data!O:O,Data!O:O,"<>",Data!$A:$A,$A4,Data!$D:$D,$B$30))/(sumifs(Data!$D:$D,Data!O:O,"<>",Data!$A:$A,$A4,Data!$D:$D,$B$30)-countifs(Data!O:O,"<>",Data!$A:$A,$A4,Data!$D:$D,$B$30))) | N4: =if(COUNTIFS(Data!P:P,"<>",Data!$A:$A,$A4,Data!$D:$D,$B$30)<$B$31,"",(sumifs(Data!$D:$D,Data!P:P,"<>",Data!$A:$A,$A4,Data!$D:$D,$B$30)-sumifs(Data!P:P,Data!P:P,"<>",Data!$A:$A,$A4,Data!$D:$D,$B$30))/(sumifs(Data!$D:$D,Data!P:P,"<>",Data!$A:$A,$A4,Data!$D:$D,$B$30)-countifs(Data!P:P,"<>",Data!$A:$A,$A4,Data!$D:$D,$B$30))) | O4: =if(COUNTIFS(Data!Q:Q,"<>",Data!$A:$A,$A4,Data!$D:$D,$B$30)<$B$31,"",(sumifs(Data!$D:$D,Data!Q:Q,"<>",Data!$A:$A,$A4,Data!$D:$D,$B$30)-sumifs(Data!Q:Q,Data!Q:Q,"<>",Data!$A:$A,$A4,Data!$D:$D,$B$30))/(sumifs(Data!$D:$D,Data!Q:Q,"<>",Data!$A:$A,$A4,Data!$D:$D,$B$30)-countifs(Data!Q:Q,"<>",Data!$A:$A,$A4,Data!$D:$D,$B$30))) | P4: =if(COUNTIFS(Data!R:R,"<>",Data!$A:$A,$A4,Data!$D:$D,$B$30)<$B$31,"",(sumifs(Data!$D:$D,Data!R:R,"<>",Data!$A:$A,$A4,Data!$D:$D,$B$30)-sumifs(Data!R:R,Data!R:R,"<>",Data!$A:$A,$A4,Data!$D:$D,$B$30))/(sumifs(Data!$D:$D,Data!R:R,"<>",Data!$A:$A,$A4,Data!$D:$D,$B$30)-countifs(Data!R:R,"<>",Data!$A:$A,$A4,Data!$D:$D,$B$30))) | Q4: =if(COUNTIFS(Data!S:S,"<>",Data!$A:$A,$A4,Data!$D:$D,$B$30)<$B$31,"",(sumifs(Data!$D:$D,Data!S:S,"<>",Data!$A:$A,$A4,Data!$D:$D,$B$30)-sumifs(Data!S:S,Data!S:S,"<>",Data!$A:$A,$A4,Data!$D:$D,$B$30))/(sumifs(Data!$D:$D,Data!S:S,"<>",Data!$A:$A,$A4,Data!$D:$D,$B$30)-countifs(Data!S:S,"<>",Data!$A:$A,$A4,Data!$D:$D,$B$30))) | R4: =if(COUNTIFS(Data!T:T,"<>",Data!$A:$A,$A4,Data!$D:$D,$B$30)<$B$31,"",(sumifs(Data!$D:$D,Data!T:T,"<>",Data!$A:$A,$A4,Data!$D:$D,$B$30)-sumifs(Data!T:T,Data!T:T,"<>",Data!$A:$A,$A4,Data!$D:$D,$B$30))/(sumifs(Data!$D:$D,Data!T:T,"<>",Data!$A:$A,$A4,Data!$D:$D,$B$30)-countifs(Data!T:T,"<>",Data!$A:$A,$A4,Data!$D:$D,$B$30))) | S4: =if(COUNTIFS(Data!U:U,"<>",Data!$A:$A,$A4,Data!$D:$D,$B$30)<$B$31,"",(sumifs(Data!$D:$D,Data!U:U,"<>",Data!$A:$A,$A4,Data!$D:$D,$B$30)-sumifs(Data!U:U,Data!U:U,"<>",Data!$A:$A,$A4,Data!$D:$D,$B$30))/(sumifs(Data!$D:$D,Data!U:U,"<>",Data!$A:$A,$A4,Data!$D:$D,$B$30)-countifs(Data!U:U,"<>",Data!$A:$A,$A4,Data!$D:$D,$B$30))) | T4: =if(COUNTIFS(Data!V:V,"<>",Data!$A:$A,$A4,Data!$D:$D,$B$30)<$B$31,"",(sumifs(Data!$D:$D,Data!V:V,"<>",Data!$A:$A,$A4,Data!$D:$D,$B$30)-sumifs(Data!V:V,Data!V:V,"<>",Data!$A:$A,$A4,Data!$D:$D,$B$30))/(sumifs(Data!$D:$D,Data!V:V,"<>",Data!$A:$A,$A4,Data!$D:$D,$B$30)-countifs(Data!V:V,"<>",Data!$A:$A,$A4,Data!$D:$D,$B$30)))
A5: King of Tokyo | B5: =countif(Data!A:A,"="&A5) -> 17 | C5: =if(COUNTIFS(Data!E:E,"<>",Data!$A:$A,$A5,Data!$D:$D,$B$30)<$B$31,"",(sumifs(Data!$D:$D,Data!E:E,"<>",Data!$A:$A,$A5,Data!$D:$D,$B$30)-sumifs(Data!E:E,Data!E:E,"<>",Data!$A:$A,$A5,Data!$D:$D,$B$30))/(sumifs(Data!$D:$D,Data!E:E,"<>",Data!$A:$A,$A5,Data!$D:$D,$B$30)-countifs(Data!E:E,"<>",Data!$A:$A,$A5,Data!$D:$D,$B$30))) -> 0.38461538 | D5: =if(COUNTIFS(Data!F:F,"<>",Data!$A:$A,$A5,Data!$D:$D,$B$30)<$B$31,"",(sumifs(Data!$D:$D,Data!F:F,"<>",Data!$A:$A,$A5,Data!$D:$D,$B$30)-sumifs(Data!F:F,Data!F:F,"<>",Data!$A:$A,$A5,Data!$D:$D,$B$30))/(sumifs(Data!$D:$D,Data!F:F,"<>",Data!$A:$A,$A5,Data!$D:$D,$B$30)-countifs(Data!F:F,"<>",Data!$A:$A,$A5,Data!$D:$D,$B$30))) -> 0.57692308 | E5: =if(COUNTIFS(Data!G:G,"<>",Data!$A:$A,$A5,Data!$D:$D,$B$30)<$B$31,"",(sumifs(Data!$D:$D,Data!G:G,"<>",Data!$A:$A,$A5,Data!$D:$D,$B$30)-sumifs(Data!G:G,Data!G:G,"<>",Data!$A:$A,$A5,Data!$D:$D,$B$30))/(sumifs(Data!$D:$D,Data!G:G,"<>",Data!$A:$A,$A5,Data!$D:$D,$B$30)-countifs(Data!G:G,"<>",Data!$A:$A,$A5,Data!$D:$D,$B$30))) | F5: =if(COUNTIFS(Data!H:H,"<>",Data!$A:$A,$A5,Data!$D:$D,$B$30)<$B$31,"",(sumifs(Data!$D:$D,Data!H:H,"<>",Data!$A:$A,$A5,Data!$D:$D,$B$30)-sumifs(Data!H:H,Data!H:H,"<>",Data!$A:$A,$A5,Data!$D:$D,$B$30))/(sumifs(Data!$D:$D,Data!H:H,"<>",Data!$A:$A,$A5,Data!$D:$D,$B$30)-countifs(Data!H:H,"<>",Data!$A:$A,$A5,Data!$D:$D,$B$30))) | G5: =if(COUNTIFS(Data!I:I,"<>",Data!$A:$A,$A5,Data!$D:$D,$B$30)<$B$31,"",(sumifs(Data!$D:$D,Data!I:I,"<>",Data!$A:$A,$A5,Data!$D:$D,$B$30)-sumifs(Data!I:I,Data!I:I,"<>",Data!$A:$A,$A5,Data!$D:$D,$B$30))/(sumifs(Data!$D:$D,Data!I:I,"<>",Data!$A:$A,$A5,Data!$D:$D,$B$30)-countifs(Data!I:I,"<>",Data!$A:$A,$A5,Data!$D:$D,$B$30))) | H5: =if(COUNTIFS(Data!J:J,"<>",Data!$A:$A,$A5,Data!$D:$D,$B$30)<$B$31,"",(sumifs(Data!$D:$D,Data!J:J,"<>",Data!$A:$A,$A5,Data!$D:$D,$B$30)-sumifs(Data!J:J,Data!J:J,"<>",Data!$A:$A,$A5,Data!$D:$D,$B$30))/(sumifs(Data!$D:$D,Data!J:J,"<>",Data!$A:$A,$A5,Data!$D:$D,$B$30)-countifs(Data!J:J,"<>",Data!$A:$A,$A5,Data!$D:$D,$B$30))) | I5: =if(COUNTIFS(Data!K:K,"<>",Data!$A:$A,$A5,Data!$D:$D,$B$30)<$B$31,"",(sumifs(Data!$D:$D,Data!K:K,"<>",Data!$A:$A,$A5,Data!$D:$D,$B$30)-sumifs(Data!K:K,Data!K:K,"<>",Data!$A:$A,$A5,Data!$D:$D,$B$30))/(sumifs(Data!$D:$D,Data!K:K,"<>",Data!$A:$A,$A5,Data!$D:$D,$B$30)-countifs(Data!K:K,"<>",Data!$A:$A,$A5,Data!$D:$D,$B$30))) | J5: =if(COUNTIFS(Data!L:L,"<>",Data!$A:$A,$A5,Data!$D:$D,$B$30)<$B$31,"",(sumifs(Data!$D:$D,Data!L:L,"<>",Data!$A:$A,$A5,Data!$D:$D,$B$30)-sumifs(Data!L:L,Data!L:L,"<>",Data!$A:$A,$A5,Data!$D:$D,$B$30))/(sumifs(Data!$D:$D,Data!L:L,"<>",Data!$A:$A,$A5,Data!$D:$D,$B$30)-countifs(Data!L:L,"<>",Data!$A:$A,$A5,Data!$D:$D,$B$30))) | K5: =if(COUNTIFS(Data!M:M,"<>",Data!$A:$A,$A5,Data!$D:$D,$B$30)<$B$31,"",(sumifs(Data!$D:$D,Data!M:M,"<>",Data!$A:$A,$A5,Data!$D:$D,$B$30)-sumifs(Data!M:M,Data!M:M,"<>",Data!$A:$A,$A5,Data!$D:$D,$B$30))/(sumifs(Data!$D:$D,Data!M:M,"<>",Data!$A:$A,$A5,Data!$D:$D,$B$30)-countifs(Data!M:M,"<>",Data!$A:$A,$A5,Data!$D:$D,$B$30))) | L5: =if(COUNTIFS(Data!N:N,"<>",Data!$A:$A,$A5,Data!$D:$D,$B$30)<$B$31,"",(sumifs(Data!$D:$D,Data!N:N,"<>",Data!$A:$A,$A5,Data!$D:$D,$B$30)-sumifs(Data!N:N,Data!N:N,"<>",Data!$A:$A,$A5,Data!$D:$D,$B$30))/(sumifs(Data!$D:$D,Data!N:N,"<>",Data!$A:$A,$A5,Data!$D:$D,$B$30)-countifs(Data!N:N,"<>",Data!$A:$A,$A5,Data!$D:$D,$B$30))) | M5: =if(COUNTIFS(Data!O:O,"<>",Data!$A:$A,$A5,Data!$D:$D,$B$30)<$B$31,"",(sumifs(Data!$D:$D,Data!O:O,"<>",Data!$A:$A,$A5,Data!$D:$D,$B$30)-sumifs(Data!O:O,Data!O:O,"<>",Data!$A:$A,$A5,Data!$D:$D,$B$30))/(sumifs(Data!$D:$D,Data!O:O,"<>",Data!$A:$A,$A5,Data!$D:$D,$B$30)-countifs(Data!O:O,"<>",Data!$A:$A,$A5,Data!$D:$D,$B$30))) | N5: =if(COUNTIFS(Data!P:P,"<>",Data!$A:$A,$A5,Data!$D:$D,$B$30)<$B$31,"",(sumifs(Data!$D:$D,Data!P:P,"<>",Data!$A:$A,$A5,Data!$D:$D,$B$30)-sumifs(Data!P:P,Data!P:P,"<>",Data!$A:$A,$A5,Data!$D:$D,$B$30))/(sumifs(Data!$D:$D,Data!P:P,"<>",Data!$A:$A,$A5,Data!$D:$D,$B$30)-countifs(Data!P:P,"<>",Data!$A:$A,$A5,Data!$D:$D,$B$30))) | O5: =if(COUNTIFS(Data!Q:Q,"<>",Data!$A:$A,$A5,Data!$D:$D,$B$30)<$B$31,"",(sumifs(Data!$D:$D,Data!Q:Q,"<>",Data!$A:$A,$A5,Data!$D:$D,$B$30)-sumifs(Data!Q:Q,Data!Q:Q,"<>",Data!$A:$A,$A5,Data!$D:$D,$B$30))/(sumifs(Data!$D:$D,Data!Q:Q,"<>",Data!$A:$A,$A5,Data!$D:$D,$B$30)-countifs(Data!Q:Q,"<>",Data!$A:$A,$A5,Data!$D:$D,$B$30))) | P5: =if(COUNTIFS(Data!R:R,"<>",Data!$A:$A,$A5,Data!$D:$D,$B$30)<$B$31,"",(sumifs(Data!$D:$D,Data!R:R,"<>",Data!$A:$A,$A5,Data!$D:$D,$B$30)-sumifs(Data!R:R,Data!R:R,"<>",Data!$A:$A,$A5,Data!$D:$D,$B$30))/(sumifs(Data!$D:$D,Data!R:R,"<>",Data!$A:$A,$A5,Data!$D:$D,$B$30)-countifs(Data!R:R,"<>",Data!$A:$A,$A5,Data!$D:$D,$B$30))) | Q5: =if(COUNTIFS(Data!S:S,"<>",Data!$A:$A,$A5,Data!$D:$D,$B$30)<$B$31,"",(sumifs(Data!$D:$D,Data!S:S,"<>",Data!$A:$A,$A5,Data!$D:$D,$B$30)-sumifs(Data!S:S,Data!S:S,"<>",Data!$A:$A,$A5,Data!$D:$D,$B$30))/(sumifs(Data!$D:$D,Data!S:S,"<>",Data!$A:$A,$A5,Data!$D:$D,$B$30)-countifs(Data!S:S,"<>",Data!$A:$A,$A5,Data!$D:$D,$B$30))) | R5: =if(COUNTIFS(Data!T:T,"<>",Data!$A:$A,$A5,Data!$D:$D,$B$30)<$B$31,"",(sumifs(Data!$D:$D,Data!T:T,"<>",Data!$A:$A,$A5,Data!$D:$D,$B$30)-sumifs(Data!T:T,Data!T:T,"<>",Data!$A:$A,$A5,Data!$D:$D,$B$30))/(sumifs(Data!$D:$D,Data!T:T,"<>",Data!$A:$A,$A5,Data!$D:$D,$B$30)-countifs(Data!T:T,"<>",Data!$A:$A,$A5,Data!$D:$D,$B$30))) | S5: =if(COUNTIFS(Data!U:U,"<>",Data!$A:$A,$A5,Data!$D:$D,$B$30)<$B$31,"",(sumifs(Data!$D:$D,Data!U:U,"<>",Data!$A:$A,$A5,Data!$D:$D,$B$30)-sumifs(Data!U:U,Data!U:U,"<>",Data!$A:$A,$A5,Data!$D:$D,$B$30))/(sumifs(Data!$D:$D,Data!U:U,"<>",Data!$A:$A,$A5,Data!$D:$D,$B$30)-countifs(Data!U:U,"<>",Data!$A:$A,$A5,Data!$D:$D,$B$30))) | T5: =if(COUNTIFS(Data!V:V,"<>",Data!$A:$A,$A5,Data!$D:$D,$B$30)<$B$31,"",(sumifs(Data!$D:$D,Data!V:V,"<>",Data!$A:$A,$A5,Data!$D:$D,$B$30)-sumifs(Data!V:V,Data!V:V,"<>",Data!$A:$A,$A5,Data!$D:$D,$B$30))/(sumifs(Data!$D:$D,Data!V:V,"<>",Data!$A:$A,$A5,Data!$D:$D,$B$30)-countifs(Data!V:V,"<>",Data!$A:$A,$A5,Data!$D:$D,$B$30)))
